Workbook
Name att_actdate: Attribution!$F$14:$F$21
Name att_actlr: Attribution!$C$10
Name att_actpct: Attribution!$E$14:$E$21
Name att_asof: Attribution!$C$7
Name att_m0: Attribution!$C$6
Name att_m1: Attribution!$C$8
Name att_m2: Attribution!$C$9
Name att_reconciles: Attribution!$B$32
Name br_selrow: Bridge!$F$36
Name calc_amod_p: _calc!$K$4:$K$72
Name calc_amod_p1: _calc!$L$4:$L$72
Name calc_aother: _calc!$R$4:$R$72
Name calc_arate_p: _calc!$I$4:$I$72
Name calc_arate_p1: _calc!$J$4:$J$72
Name calc_bu: _calc!$U$4:$U$72
Name calc_carry: _calc!$Q$4:$Q$72
Name calc_crl: _calc!$C$4:$C$72
Name calc_cylr_p: _calc!$N$4:$N$72
Name calc_cylr_p1: _calc!$O$4:$O$72
Name calc_cylr_prog: _calc!$CO$4:$CO$72
Name calc_cylr1_prog: _calc!$CP$4:$CP$72
Name calc_echg: _calc!$P$4:$P$72
Name calc_ecy_p: _calc!$E$4:$E$72
Name calc_ecy_p1: _calc!$F$4:$F$72
Name calc_ecy_pm1: _calc!$D$4:$D$72
Name calc_ep: _calc!$V$4:$V$72
Name calc_key: _calc!$A$4:$A$72
Name calc_lrcur: _calc!$M$4:$M$72
Name calc_mbar_p: _calc!$G$4:$G$72
Name calc_mbar_p1: _calc!$H$4:$H$72
Name calc_netmode: _calc!$AK$4:$AK$72
Name calc_netx: _calc!$AL$4:$AL$72
Name calc_nplanned: _calc!$CV$4:$CV$72
Name calc_ntaken: _calc!$CU$4:$CU$72
Name calc_proggap: _calc!$CT$4:$CT$72
Name calc_progident: _calc!$CS$4:$CS$72
Name calc_state: _calc!$T$4:$T$72
Name calc_term: _calc!$B$4:$B$72
Name calc_trend: _calc!$S$4:$S$72
Name calc_w_amod: _calc!$AD$4:$AD$72
Name calc_w_amod1: _calc!$AI$4:$AI$72
Name calc_w_aother: _calc!$CN$4:$CN$72
Name calc_w_arate: _calc!$AB$4:$AB$72
Name calc_w_arate1: _calc!$AH$4:$AH$72
Name calc_w_crl: _calc!$Z$4:$Z$72
Name calc_w_cylr: _calc!$AF$4:$AF$72
Name calc_w_cylr_prog: _calc!$CQ$4:$CQ$72
Name calc_w_cylr1: _calc!$AJ$4:$AJ$72
Name calc_w_cylr1_prog: _calc!$CR$4:$CR$72
Name calc_w_ecy: _calc!$AA$4:$AA$72
Name calc_w_lrcur: _calc!$AE$4:$AE$72
Name calc_w_m0: _calc!$X$4:$X$72
Name calc_w_m1: _calc!$Y$4:$Y$72
Name calc_w_mbar: _calc!$AC$4:$AC$72
Name calc_w_mind: _calc!$W$4:$W$72
Name calc_w_trend: _calc!$AG$4:$AG$72
Name ck_overall: Checks!$C$3
Name fd_avgdel: 'Flow Dashboard'!$U$79
Name fd_tkw: _calc!$N$4729:$N$4776
Name lr_aother: Inputs!$N$12:$N$80

Sheet Read Me
B2: Calendar-Year Plan Loss Ratio Workbook — Inland Marine
B3: Plan year 2027 | one workbook per LOB; rows are BU x state | version 2.7.0 | built 07/31/2026 by src/build_workbook.py (generator v2.7.0) | classic formula mode (Excel-2007-era functions only)
B5: Where to go
B6: =HYPERLINK("#Control!A1","Control") -> Control | C6: Pick the plan year, BU and state; global toggles; the six headline KPIs.
B7: =HYPERLINK("#Inputs!A1","Inputs") -> Inputs | C7: Enter or paste the book: loss ratios and mods (tbl_LR), seasonality, and the policy term.
B8: =HYPERLINK("#'Rate Log'!A1","Rate Log") -> Rate Log | C8: Enter or paste rate changes — every row shows its combo's plan LR moving as you type.
B9: =HYPERLINK("#Portfolio!A1","Portfolio") -> Portfolio | C9: Every BU x state combo at once, plus the Decision Board: top movers, contribution to the book, the portfolio bridge.
B10: =HYPERLINK("#'State Summary'!A1","State Summary") -> State Summary | C10: One row per state with a BU filter ('All' = EP-weighted) — the leadership exhibit. Rate changes carry T/P status tokens and the plan LR is the visible product of the four factors beside it.
B11: =HYPERLINK("#'Program Flow'!A1","Program Flow") -> Program Flow | C11: What the program AS LOGGED is delivering — state x month YoY grids for the written rate, mod, and net legs (the descriptive twin of Net Delivery). 'All' = the EP-weighted book view.
B12: =HYPERLINK("#'Net Delivery'!A1","Net Delivery") -> Net Delivery | C12: For net-target combos: the month-by-month rate leg and the pricing change that satisfies the target, plus the suggested filing.
B13: =HYPERLINK("#Bridge!A1","Bridge") -> Bridge | C13: The selected combo's answer: projected LR -> CY plan LR, factor by factor.
B14: =HYPERLINK("#Walkthrough!A1","Walkthrough") -> Walkthrough | C14: The fully worked example — every calculation for the selected combo, start to finish.
B15: =HYPERLINK("#'One-Pager'!A1","One-Pager") -> One-Pager | C15: A print-ready brief of the selected combo — the page you hand a VP.
B16: =HYPERLINK("#'Flow Dashboard'!A1","Flow Dashboard") -> Flow Dashboard | C16: When rate and price actually earn in — monthly flow charts, the runway, the carryover ledger.
B17: =HYPERLINK("#Scenarios!A1","Scenarios") -> Scenarios | C17: Four what-if lever sets side by side against Base (S1 ships seeded as a demo).
B18: =HYPERLINK("#Compare!A1","Compare") -> Compare | C18: Any two combos side by side across the full factor chain.
B19: =HYPERLINK("#Solver!A1","Solver") -> Solver | C19: Inverse planning: the required change for a target CY LR, and timing sensitivity — can follow Control or solve any combo.
B20: =HYPERLINK("#Attribution!A1","Attribution") -> Attribution | C20: After the year closes: decompose actual vs plan into rate, timing, mod, and loss.
B21: =HYPERLINK("#'Rate Engine'!A1","Rate Engine") -> Rate Engine | C21: Audit trail: 48 writing cohorts x earning matrix behind the earned rate level.
B22: =HYPERLINK("#'Mod Engine'!A1","Mod Engine") -> Mod Engine | C22: Audit trail: the written schedule-mod path and the earned mod.
B23: =HYPERLINK("#Checks!A1","Checks") -> Checks | C23: The trust panel — must show ALL CHECKS PASS.
B24: =HYPERLINK("#Methodology!A1","Methodology") -> Methodology | C24: The full writeup: formulas as implemented, conventions, named ranges.
B25: _lists / _calc / _netcalc / _oracle | C25: Hidden machinery: validation lists, the per-combo engine blocks, the Net Delivery blocks, and the baked oracle constants. Nothing to edit there.
B27: What this workbook does
C28: Converts the projected loss ratio from a rate level indication (policy-year basis, rate fully earned) into a CALENDAR-YEAR plan loss ratio at the plan year's average earned rate level — the number a plan is actually written against.
C29: Method: standard on-leveling (Werner & Modlin, Basic Ratemaking, Ch. 5) through a monthly written-index x earning-matrix engine, extended with a schedule-mod adjustment, optional seasonality, and an optional net rate selection.
C30: Every displayed figure is calculated, never typed, and ties to an independent Python oracle at build time; the Checks sheet proves the workbook's integrity live.
B32: THE BRIDGE IN ONE LINE | C32: CY plan LR = projected LR (current level) x rate earn-in x mod drift x other adj
C33: The following year (indicative) additionally applies one year of net trend and uses that year's earn-in factors.
B35: Quick start
B36: 1. | C36: Replace the SAMPLE rows with your book: tbl_LR, seasonality, and the policy term on Inputs; the rate change log (one row per change) on the Rate Log sheet. Do not insert or delete rows — spare rows are provided. Rename BUs and states directly in tbl_LR: every dropdown and exhibit follows the live roster automatically.
B37: 2. | C37: On Control, pick the plan year, BU, and state, and set the global toggles (seasonality, the mod-adjustment master switch, the default net trend).
B38: 3. | C38: Read the KPI row on Control; audit any figure through Rate Engine -> Mod Engine -> Bridge.
B39: 4. | C39: State Summary is the per-state exhibit (BU filter; 'All' combines on adjusted-EP weights). Portfolio shows every combo at once.
B40: 5. | C40: Scenarios: up to four lever sets (rate points, timing shift, achievement, mod path, net selection) side by side against Base.
B41: 6. | C41: Optional NET RATE SELECTION per combo (tbl_LR): a combined rate + price year-over-year target from 1/1 of the plan year — see Methodology 6b for exactly what it supersedes.
B42: 7. | C42: Solver: Mode A returns the single change needed for a target CY LR at a chosen date (it replaces the whole planned program — see the note there); Mode B shows the full-year LR under each possible start month.
B43: 8. | C43: Attribution (after the year closes): enter achieved changes, actual dates, the actual mod path, and the actual CY LR for a plan-vs-actual waterfall.
B44: 9. | C44: Checks must show ALL CHECKS PASS (also surfaced on Control). Oracle-tie rows apply only while the seeded sample is intact and report N/A afterward — regenerate the workbook to re-bake them for your data. For a new plan year, regenerate from config/config.yaml and paste inputs into the fresh copy (table schemas are stable).
B46: Color legend
...

Sheet Control
B2: Calendar-Year Plan Loss Ratio — Inland Marine
B3: Plan year 2027 | one workbook per LOB; combos are BU x state | generated by src/build_workbook.py v2.7.0 | classic formula mode
B4: Jump to: | C4: =HYPERLINK("#Inputs!A1","Inputs") -> Inputs | D4: =HYPERLINK("#'Rate Log'!A1","Rate Log") -> Rate Log | E4: =HYPERLINK("#Portfolio!A1","Portfolio") -> Portfolio | F4: =HYPERLINK("#'State Summary'!A1","State Summary") -> State Summary | G4: =HYPERLINK("#'Program Flow'!A1","Program Flow") -> Program Flow | H4: =HYPERLINK("#'Net Delivery'!A1","Net Delivery") -> Net Delivery | I4: =HYPERLINK("#Bridge!A1","Bridge") -> Bridge | J4: =HYPERLINK("#Walkthrough!A1","Walkthrough") -> Walkthrough | K4: =HYPERLINK("#One-Pager!A1","One-Pager") -> One-Pager | L4: =HYPERLINK("#'Flow Dashboard'!A1","Flow Dashboard") -> Flow Dashboard | M4: =HYPERLINK("#Scenarios!A1","Scenarios") -> Scenarios | N4: =HYPERLINK("#Compare!A1","Compare") -> Compare | O4: =HYPERLINK("#Solver!A1","Solver") -> Solver | P4: =HYPERLINK("#Attribution!A1","Attribution") -> Attribution | Q4: =HYPERLINK("#'Rate Engine'!A1","Rate Engine") -> Rate Engine | R4: =HYPERLINK("#'Mod Engine'!A1","Mod Engine") -> Mod Engine | S4: =HYPERLINK("#Checks!A1","Checks") -> Checks | T4: =HYPERLINK("#Methodology!A1","Methodology") -> Methodology | U4: =HYPERLINK("#'Read Me'!A1","Read Me") -> Read Me
B5: Selection
B6: Plan year (P) | C6: 2027 | E6: Selected key | F6: =$C$7&"|"&$C$8 -> ABD|AZ
B7: Business unit | C7: ABD | E7: Combo found in tbl_LR? | F7: =IF($G$7,"yes","NO — add the row to tbl_LR") -> yes | G7: =COUNTIF(lr_key,$F$6)>0 -> TRUE
B8: State | C8: AZ | E8: Policy term (months) | F8: =nr_TermMonths -> 6
B9: Scenario in focus | C9: Base | E9: Line of business | F9: Inland Marine
B10: =IF(nr_PlanYear=2027,"","NOTE: plan year differs from the generated 2027. All CALCULATIONS follow the plan year entered above; sample data and some printed notes still describe the generated book. Regenerate for a clean copy.")
B11: Global toggles
B12: Seasonality (written weights) | C12: OFF | D12: ON applies tbl_Seasonality weights for the selected STATE; OFF = uniform writings (classic parallelogram).
B13: Mod adjustment (master) | C13: ON | D13: Set OFF if the indication's premium trend already reflects schedule mod drift — otherwise the drift is double-counted.
B14: Projected-LR KPI shows | C14: As input
B15: Default net trend for CY 2028 | C15: 0 | D15: Annual net loss-over-premium trend applied once for the CY 2028 view wherever a combo's tbl_LR trend cell is blank; a per-state entry overrides this default.
B16: =IF(nr_SelOK,"","WARNING: the selected BU | state has no row in tbl_LR - engines show neutral factors until a row is added.")
B17: Key results — selected BU x state
B18: =IF(nr_BasisDisp="As input","Projected LR (as input)","Projected LR (current level)") -> Projected LR (as input) | D18: ="CY "&nr_PlanYear&" plan loss ratio" -> CY 2027 plan loss ratio | F18: ="CY earned rate chg vs indication" -> CY earned rate chg vs indication | H18: ="Carryover into "&(nr_PlanYear+1) -> Carryover into 2028 | J18: ="Written mod: current / projected" -> Written mod: current / projected | L18: ="Checks status" -> Checks status | N18: ="Book: program vs asserted" -> Book: program vs asserted
B19: =IF(nr_SelOK,IF(nr_BasisDisp="As input",nr_LRproj,nr_LRcur),"—") -> 0.65 | D19: =IF(nr_SelOK,nr_CYLR_P,"—") -> 0.61816314 | F19: =IF(nr_SelOK,nr_EChgVsInd,"—") -> 0.025 | H19: =IF(nr_SelOK,nr_YoY_P1,"—") -> 0.024390244 | J19: =IF(nr_SelOK,nr_M0,"—") -> 0.86 | K19: =IF(nr_SelOK,nr_M1,"—") -> 0.89 | L19: =ck_overall -> ALL CHECKS PASS | N19: =IF(OR(SUMPRODUCT(calc_netmode)=0,SUM(calc_ep)=0),"—",(SUM(calc_w_cylr_prog)-SUM(calc_w_cylr))/SUM(calc_ep)*100) -> -0.010987577
B20: from the rate level indication | D20: projected LR x rate earn-in x mod drift x other | F20: how the year's earned rate compares with the level the indication assumed | H20: earned rate change already locked in for next year | J20: current written mod / projected at plan-year end | L20: see the Checks sheet | N20: plan LR if you book the logged program instead of the net target
B22: Rate and price flow summary | F22: Compare with another combo
B23: Metric | C23: ="CY "&nr_PlanYear -> CY 2027 | D23: ="CY "&(nr_PlanYear+1)&" (indicative)" -> CY 2028 (indicative) | F23: This view | G23: =nr_SelKey -> ABD|AZ
B24: Earned rate level (E_CY) | C24: =nr_ECY_P -> 1.12996 | D24: =nr_ECY_P1 -> 1.15752 | F24: Compare to: business unit | I24: =IF(OR($G$24="",$G$25=""),"",$G$24&"|"&$G$25)
B25: Rate earn-in factor (A_rate) | C25: =nr_Arate_P -> 0.97560976 | D25: =nr_Arate_P1 -> 0.95238095 | F25: Compare to: state | I25: =IF($I$24="",0,IF(COUNTIF(calc_key,$I$24)=0,0,MATCH($I$24,calc_key,0))) -> 0
B26: Earned schedule mod | C26: =nr_MEarned_P -> 0.87197757 | D26: =nr_MEarned_P1 -> 0.88898067 | G26: selected | H26: compare | I26: difference
B27: Mod drift factor (A_mod) | C27: =nr_Amod_P -> 0.97479572 | D27: =nr_Amod_P1 -> 0.95615127 | F27: Projected LR (current level) | G27: =IF(nr_SelOK,nr_LRcur,"—") -> 0.65 | H27: =IF($I$25=0,"—",INDEX(calc_lrcur,$I$25)) -> — | I27: =IF(OR($I$25=0,NOT(nr_SelOK)),"",IF(AND(ISNUMBER($G27),ISNUMBER($H27)),$H27-$G27,""))
B28: Earned rate chg (year over year) | C28: =nr_YoY_P -> 0.07044335 | D28: =nr_YoY_P1 -> 0.024390244 | F28: ="CY "&nr_PlanYear&" plan LR" -> CY 2027 plan LR | G28: =IF(nr_SelOK,nr_CYLR_P,"—") -> 0.61816314 | H28: =IF($I$25=0,"—",INDEX(calc_cylr_p,$I$25)) -> — | I28: =IF(OR($I$25=0,NOT(nr_SelOK)),"",IF(AND(ISNUMBER($G28),ISNUMBER($H28)),$H28-$G28,""))
B29: CY plan loss ratio | C29: =nr_CYLR_P -> 0.61816314 | D29: =nr_CYLR_P1 -> 0.59190317 | F29: Rate earn-in (A_rate) | G29: =IF(nr_SelOK,nr_Arate_P,"—") -> 0.97560976 | H29: =IF($I$25=0,"—",INDEX(calc_arate_p,$I$25)) -> — | I29: =IF(OR($I$25=0,NOT(nr_SelOK)),"",IF(AND(ISNUMBER($G29),ISNUMBER($H29)),$H29-$G29,""))
B30: Next-year column is indicative — see the canonical caveat on the Bridge. | F30: Mod drift (A_mod) | G30: =IF(nr_SelOK,nr_Amod_P,"—") -> 0.97479572 | H30: =IF($I$25=0,"—",INDEX(calc_amod_p,$I$25)) -> — | I30: =IF(OR($I$25=0,NOT(nr_SelOK)),"",IF(AND(ISNUMBER($G30),ISNUMBER($H30)),$H30-$G30,""))
F31: Earned rate level (E_CY) | G31: =IF(nr_SelOK,nr_ECY_P,"—") -> 1.12996 | H31: =IF($I$25=0,"—",INDEX(calc_ecy_p,$I$25)) -> — | I31: =IF(OR($I$25=0,NOT(nr_SelOK)),"",IF(AND(ISNUMBER($G31),ISNUMBER($H31)),$H31-$G31,""))
B32: Scenario spotlight | F32: Indication rate level (CRL_ind) | G32: =IF(nr_SelOK,nr_CRLind,"—") -> 1.1024 | H32: =IF($I$25=0,"—",INDEX(calc_crl,$I$25)) -> — | I32: =IF(OR($I$25=0,NOT(nr_SelOK)),"",IF(AND(ISNUMBER($G32),ISNUMBER($H32)),$H32-$G32,""))
B33: Scenario in focus | C33: =nr_SelScenario -> Base | F33: ="Carryover into "&(nr_PlanYear+1) -> Carryover into 2028 | G33: =IF(nr_SelOK,nr_YoY_P1,"—") -> 0.024390244 | H33: =IF($I$25=0,"—",INDEX(calc_carry,$I$25)) -> — | I33: =IF(OR($I$25=0,NOT(nr_SelOK)),"",IF(AND(ISNUMBER($G33),ISNUMBER($H33)),$H33-$G33,""))
B34: CY plan LR under scenario | C34: =INDEX(sc_res_cylr,MATCH(nr_SelScenario,sc_res_names,0)) -> 0.61816314 | F34: ="CY "&(nr_PlanYear+1)&" plan LR" -> CY 2028 plan LR | G34: =IF(nr_SelOK,nr_CYLR_P1,"—") -> 0.59190317 | H34: =IF($I$25=0,"—",INDEX(calc_cylr_p1,$I$25)) -> — | I34: =IF(OR($I$25=0,NOT(nr_SelOK)),"",IF(AND(ISNUMBER($G34),ISNUMBER($H34)),$H34-$G34,""))
B35: Delta vs Base | C35: =(INDEX(sc_res_cylr,MATCH(nr_SelScenario,sc_res_names,0))-nr_CYLR_P)*100 -> 0 | F35: Pick a BU and state to light this up; the compare column reads the same hidden all-combo engine every exhibit uses.
B37: Scenario definitions live on the Scenarios sheet; the Bridge and engine sheets always show Base inputs (see Methodology).

Sheet Inputs
A1: Inputs — Inland Marine
A2: Loss-ratio and mod inputs (one row per BU x state), seasonality, and the policy term — blue font = enter values; yellow fill = required. Rate changes live on the Rate Log sheet. Structure is fixed; do not insert or delete rows.
A3: Go to: | C3: =HYPERLINK("#Control!A1","Control") -> Control | E3: =HYPERLINK("#'Rate Log'!A1","Rate Log") -> Rate Log | G3: =HYPERLINK("#Bridge!A1","Bridge") -> Bridge | I3: =HYPERLINK("#'State Summary'!A1","State Summary") -> State Summary | K3: =HYPERLINK("#Checks!A1","Checks") -> Checks | M3: =HYPERLINK("#'Read Me'!A1","Read Me") -> Read Me
A4: SAMPLE DATA: every populated row below is illustrative and should be replaced with your book. ABD|AZ carries the documented worked example used by the Checks sheet. | T4: tbl_LR A:R is one contiguous paste block — keys, helpers, and live results sit to the right. The rate change log lives on the Rate Log sheet.
A6: Workbook parameters
A7: Line of business | B7: Inland Marine
A8: Policy term (months) | B8: 6 | C8: Applies to every BU x state in this workbook (one workbook per LOB, D37).
A10: tbl_LR — one row per BU x state (projected LR and mod inputs). Columns A:R are one contiguous paste block. | T10: engine helper — do not edit | V10: live results (formulas — do not edit)
A11: BU | B11: State | C11: Projected loss ratio | D11: LR basis | E11: Indication selected chg (s) | F11: Mod assumed in indication (M_ind) | G11: Current avg written mod (M_0) | H11: Current mod as-of date | I11: Projected mod, end of plan yr (M_1) | J11: Mod ~1 yr before as-of (M_prior, opt) | K11: Projected mod, end plan yr+1 (M_2, opt) | L11: Adj plan EP (000s) | M11: Net trend, plan yr+1 (opt) | N11: Other adj factor (A_other) | O11: Reason for other adj | P11: Apply mod adjustment? | Q11: Net rate selection, plan yr (opt) | R11: Net rate selection, plan yr+1 (opt) | T11: Key | V11: This combo's CY plan LR | W11: Chg vs projected (pts) | X11: Rate earn-in (A_rate) | Y11: Mod drift (A_mod)
A12: ABD | B12: AZ | C12: 0.65 | D12: current | E12: 0.05 | F12: 0.85 | G12: 0.86 | H12: 46295 | I12: 0.89 | L12: 6400 | N12: 1 | P12: ON | T12: =IF(OR($A12="",$B12=""),"",$A12&"|"&$B12) -> ABD|AZ | V12: =IF($T12="","",INDEX(calc_cylr_p,1)) -> 0.61816314 | W12: =IF($T12="","",(INDEX(calc_cylr_p,1)-INDEX(calc_lrcur,1))*100) -> -3.1836864 | X12: =IF($T12="","",INDEX(calc_arate_p,1)) -> 0.97560976 | Y12: =IF($T12="","",INDEX(calc_amod_p,1)) -> 0.97479572
A13: ABD | B13: CO | C13: 0.588 | D13: current | E13: 0.05 | F13: 0.92 | G13: 0.91 | H13: 46295 | I13: 0.915 | L13: 16800 | N13: 1 | P13: ON | T13: =IF(OR($A13="",$B13=""),"",$A13&"|"&$B13) -> ABD|CO | V13: =IF($T13="","",INDEX(calc_cylr_p,2)) -> 0.57775356 | W13: =IF($T13="","",(INDEX(calc_cylr_p,2)-INDEX(calc_lrcur,2))*100) -> -1.0246436 | X13: =IF($T13="","",INDEX(calc_arate_p,2)) -> 0.97402597 | Y13: =IF($T13="","",INDEX(calc_amod_p,2)) -> 1.0087761
A14: ABD | B14: DE | C14: 0.572 | D14: current | E14: 0.05 | F14: 0.92 | G14: 0.91 | H14: 46295 | I14: 0.93 | L14: 13600 | N14: 1 | P14: ON | T14: =IF(OR($A14="",$B14=""),"",$A14&"|"&$B14) -> ABD|DE | V14: =IF($T14="","",INDEX(calc_cylr_p,3)) -> 0.57325552 | W14: =IF($T14="","",(INDEX(calc_cylr_p,3)-INDEX(calc_lrcur,3))*100) -> 0.12555247 | X14: =IF($T14="","",INDEX(calc_arate_p,3)) -> 1 | Y14: =IF($T14="","",INDEX(calc_amod_p,3)) -> 1.002195
A15: ABD | B15: FL | C15: 0.6 | D15: current | E15: 0.05 | F15: 0.92 | G15: 0.92 | H15: 46295 | I15: 0.92 | L15: 10400 | N15: 1 | P15: OFF | T15: =IF(OR($A15="",$B15=""),"",$A15&"|"&$B15) -> ABD|FL | V15: =IF($T15="","",INDEX(calc_cylr_p,4)) -> 0.6 | W15: =IF($T15="","",(INDEX(calc_cylr_p,4)-INDEX(calc_lrcur,4))*100) -> 0 | X15: =IF($T15="","",INDEX(calc_arate_p,4)) -> 1 | Y15: =IF($T15="","",INDEX(calc_amod_p,4)) -> 1
A16: ABD | B16: GA | C16: 0.584 | D16: current | E16: 0.05 | F16: 0.92 | G16: 0.91 | H16: 46295 | I16: 0.925 | L16: 7200 | N16: 1 | P16: ON | T16: =IF(OR($A16="",$B16=""),"",$A16&"|"&$B16) -> ABD|GA | V16: =IF($T16="","",INDEX(calc_cylr_p,5)) -> 0.5865574 | W16: =IF($T16="","",(INDEX(calc_cylr_p,5)-INDEX(calc_lrcur,5))*100) -> 0.25573995 | X16: =IF($T16="","",INDEX(calc_arate_p,5)) -> 1 | Y16: =IF($T16="","",INDEX(calc_amod_p,5)) -> 1.0043791
A17: ABD | B17: IA | C17: 0.568 | D17: current | E17: 0.05 | F17: 0.92 | G17: 0.91 | H17: 46295 | I17: 0.905 | J17: 0.9 | K17: 0.91 | L17: 17600 | N17: 1 | P17: ON | T17: =IF(OR($A17="",$B17=""),"",$A17&"|"&$B17) -> ABD|IA | V17: =IF($T17="","",INDEX(calc_cylr_p,6)) -> 0.56797978 | W17: =IF($T17="","",(INDEX(calc_cylr_p,6)-INDEX(calc_lrcur,6))*100) -> -0.0020222516 | X17: =IF($T17="","",INDEX(calc_arate_p,6)) -> 0.98684211 | Y17: =IF($T17="","",INDEX(calc_amod_p,6)) -> 1.0132973
A18: ABD | B18: IL | C18: 0.596 | D18: current | E18: 0.05 | F18: 0.92 | G18: 0.91 | H18: 46295 | I18: 0.92 | L18: 14400 | N18: 1 | P18: ON | T18: =IF(OR($A18="",$B18=""),"",$A18&"|"&$B18) -> ABD|IL | V18: =IF($T18="","",INDEX(calc_cylr_p,7)) -> 0.59991738 | W18: =IF($T18="","",(INDEX(calc_cylr_p,7)-INDEX(calc_lrcur,7))*100) -> 0.39173798 | X18: =IF($T18="","",INDEX(calc_arate_p,7)) -> 1 | Y18: =IF($T18="","",INDEX(calc_amod_p,7)) -> 1.0065728
A19: ABD | B19: IN | C19: 0.58 | D19: current | E19: 0.05 | F19: 0.92 | G19: 0.91 | H19: 46295 | I19: 0.9 | L19: 11200 | N19: 1 | P19: ON | T19: =IF(OR($A19="",$B19=""),"",$A19&"|"&$B19) -> ABD|IN | V19: =IF($T19="","",INDEX(calc_cylr_p,8)) -> 0.58911496 | W19: =IF($T19="","",(INDEX(calc_cylr_p,8)-INDEX(calc_lrcur,8))*100) -> 0.91149614 | X19: =IF($T19="","",INDEX(calc_arate_p,8)) -> 1.0002672 | Y19: =IF($T19="","",INDEX(calc_amod_p,8)) -> 1.0154442
A20: ABD | B20: KY | C20: 0.564 | D20: current | E20: 0.05 | F20: 0.92 | G20: 0.91 | H20: 46295 | I20: 0.915 | L20: 8000 | N20: 1 | P20: ON | T20: =IF(OR($A20="",$B20=""),"",$A20&"|"&$B20) -> ABD|KY | V20: =IF($T20="","",INDEX(calc_cylr_p,9)) -> 0.5689497 | W20: =IF($T20="","",(INDEX(calc_cylr_p,9)-INDEX(calc_lrcur,9))*100) -> 0.49497005 | X20: =IF($T20="","",INDEX(calc_arate_p,9)) -> 1 | Y20: =IF($T20="","",INDEX(calc_amod_p,9)) -> 1.0087761
A21: ABD | B21: MD | C21: 0.592 | D21: current | E21: 0.05 | F21: 0.92 | G21: 0.91 | H21: 46295 | I21: 0.93 | L21: 18400 | N21: 1 | P21: ON | T21: =IF(OR($A21="",$B21=""),"",$A21&"|"&$B21) -> ABD|MD | V21: =IF($T21="","",INDEX(calc_cylr_p,10)) -> 0.59391575 | W21: =IF($T21="","",(INDEX(calc_cylr_p,10)-INDEX(calc_lrcur,10))*100) -> 0.19157518 | X21: =IF($T21="","",INDEX(calc_arate_p,10)) -> 1.0010388 | Y21: =IF($T21="","",INDEX(calc_amod_p,10)) -> 1.002195
A22: ABD | B22: MI | C22: 0.576 | D22: current | E22: 0.05 | F22: 0.92 | G22: 0.91 | H22: 46295 | I22: 0.91 | L22: 15200 | N22: 1 | P22: ON | T22: =IF(OR($A22="",$B22=""),"",$A22&"|"&$B22) -> ABD|MI | V22: =IF($T22="","",INDEX(calc_cylr_p,11)) -> 0.58360113 | W22: =IF($T22="","",(INDEX(calc_cylr_p,11)-INDEX(calc_lrcur,11))*100) -> 0.76011325 | X22: =IF($T22="","",INDEX(calc_arate_p,11)) -> 1.0021834 | Y22: =IF($T22="","",INDEX(calc_amod_p,11)) -> 1.010989
A23: ABD | B23: MN | C23: 0.56 | D23: current | E23: 0.05 | F23: 0.92 | G23: 0.91 | H23: 46295 | I23: 0.925 | L23: 12000 | N23: 1 | P23: ON | T23: =IF(OR($A23="",$B23=""),"",$A23&"|"&$B23) -> ABD|MN | V23: =IF($T23="","",INDEX(calc_cylr_p,12)) -> 0.5624523 | W23: =IF($T23="","",(INDEX(calc_cylr_p,12)-INDEX(calc_lrcur,12))*100) -> 0.24523009 | X23: =IF($T23="","",INDEX(calc_arate_p,12)) -> 1 | Y23: =IF($T23="","",INDEX(calc_amod_p,12)) -> 1.0043791
A24: ABD | B24: NM | C24: 0.588 | D24: current | E24: 0.05 | F24: 0.92 | G24: 0.91 | H24: 46295 | I24: 0.905 | L24: 8800 | N24: 1 | P24: ON | T24: =IF(OR($A24="",$B24=""),"",$A24&"|"&$B24) -> ABD|NM | V24: =IF($T24="","",INDEX(calc_cylr_p,13)) -> 0.59576847 | W24: =IF($T24="","",(INDEX(calc_cylr_p,13)-INDEX(calc_lrcur,13))*100) -> 0.77684724 | X24: =IF($T24="","",INDEX(calc_arate_p,13)) -> 1 | Y24: =IF($T24="","",INDEX(calc_amod_p,13)) -> 1.0132117
A25: ABD | B25: NC | C25: 0.572 | D25: current | E25: 0.05 | F25: 0.92 | G25: 0.91 | H25: 46295 | I25: 0.92 | L25: 19200 | N25: 1 | P25: ON | T25: =IF(OR($A25="",$B25=""),"",$A25&"|"&$B25) -> ABD|NC | V25: =IF($T25="","",INDEX(calc_cylr_p,14)) -> 0.56447023 | W25: =IF($T25="","",(INDEX(calc_cylr_p,14)-INDEX(calc_lrcur,14))*100) -> -0.75297716 | X25: =IF($T25="","",INDEX(calc_arate_p,14)) -> 0.98039216 | Y25: =IF($T25="","",INDEX(calc_amod_p,14)) -> 1.0065728
A26: ABD | B26: OH | C26: 0.6 | D26: current | E26: 0.05 | F26: 0.92 | G26: 0.91 | H26: 46295 | I26: 0.9 | L26: 16000 | N26: 1 | P26: ON | T26: =IF(OR($A26="",$B26=""),"",$A26&"|"&$B26) -> ABD|OH | V26: =IF($T26="","",INDEX(calc_cylr_p,15)) -> 0.6092665 | W26: =IF($T26="","",(INDEX(calc_cylr_p,15)-INDEX(calc_lrcur,15))*100) -> 0.92664955 | X26: =IF($T26="","",INDEX(calc_arate_p,15)) -> 1 | Y26: =IF($T26="","",INDEX(calc_amod_p,15)) -> 1.0154442
A27: ABD | B27: PA | C27: 0.584 | D27: current | E27: 0.05 | F27: 0.92 | G27: 0.91 | H27: 46295 | I27: 0.915 | L27: 12800 | N27: 1 | P27: ON | T27: =IF(OR($A27="",$B27=""),"",$A27&"|"&$B27) -> ABD|PA | V27: =IF($T27="","",INDEX(calc_cylr_p,16)) -> 0.58912522 | W27: =IF($T27="","",(INDEX(calc_cylr_p,16)-INDEX(calc_lrcur,16))*100) -> 0.51252218 | X27: =IF($T27="","",INDEX(calc_arate_p,16)) -> 1 | Y27: =IF($T27="","",INDEX(calc_amod_p,16)) -> 1.0087761
A28: ABD | B28: SC | C28: 0.568 | D28: current | E28: 0.05 | F28: 0.92 | G28: 0.91 | H28: 46295 | I28: 0.93 | L28: 9600 | N28: 1 | P28: ON | T28: =IF(OR($A28="",$B28=""),"",$A28&"|"&$B28) -> ABD|SC | V28: =IF($T28="","",INDEX(calc_cylr_p,17)) -> 0.56924674 | W28: =IF($T28="","",(INDEX(calc_cylr_p,17)-INDEX(calc_lrcur,17))*100) -> 0.12467448 | X28: =IF($T28="","",INDEX(calc_arate_p,17)) -> 1 | Y28: =IF($T28="","",INDEX(calc_amod_p,17)) -> 1.002195
A29: ABD | B29: TN | C29: 0.596 | D29: current | E29: 0.05 | F29: 0.92 | G29: 0.91 | H29: 46295 | I29: 0.91 | L29: 6400 | N29: 1 | P29: ON | T29: =IF(OR($A29="",$B29=""),"",$A29&"|"&$B29) -> ABD|TN | V29: =IF($T29="","",INDEX(calc_cylr_p,18)) -> 0.59839394 | W29: =IF($T29="","",(INDEX(calc_cylr_p,18)-INDEX(calc_lrcur,18))*100) -> 0.23939371 | X29: =IF($T29="","",INDEX(calc_arate_p,18)) -> 0.99310345 | Y29: =IF($T29="","",INDEX(calc_amod_p,18)) -> 1.010989
A30: ABD | B30: VA | C30: 0.58 | D30: current | E30: 0.05 | F30: 0.92 | G30: 0.91 | H30: 46295 | I30: 0.925 | L30: 16800 | N30: 1 | P30: ON | T30: =IF(OR($A30="",$B30=""),"",$A30&"|"&$B30) -> ABD|VA | V30: =IF($T30="","",INDEX(calc_cylr_p,19)) -> 0.58253988 | W30: =IF($T30="","",(INDEX(calc_cylr_p,19)-INDEX(calc_lrcur,19))*100) -> 0.2539883 | X30: =IF($T30="","",INDEX(calc_arate_p,19)) -> 1 | Y30: =IF($T30="","",INDEX(calc_amod_p,19)) -> 1.0043791
A31: ABD | B31: WV | C31: 0.564 | D31: current | E31: 0.05 | F31: 0.92 | G31: 0.91 | H31: 46295 | I31: 0.905 | L31: 13600 | N31: 1 | P31: ON | T31: =IF(OR($A31="",$B31=""),"",$A31&"|"&$B31) -> ABD|WV | V31: =IF($T31="","",INDEX(calc_cylr_p,20)) -> 0.57167611 | W31: =IF($T31="","",(INDEX(calc_cylr_p,20)-INDEX(calc_lrcur,20))*100) -> 0.76761073 | X31: =IF($T31="","",INDEX(calc_arate_p,20)) -> 1.0003932 | Y31: =IF($T31="","",INDEX(calc_amod_p,20)) -> 1.0132117
A32: ABD | B32: WI | C32: 0.592 | D32: current | E32: 0.05 | F32: 0.92 | G32: 0.91 | H32: 46295 | I32: 0.92 | L32: 10400 | N32: 1 | P32: ON | T32: =IF(OR($A32="",$B32=""),"",$A32&"|"&$B32) -> ABD|WI | V32: =IF($T32="","",INDEX(calc_cylr_p,21)) -> 0.59589109 | W32: =IF($T32="","",(INDEX(calc_cylr_p,21)-INDEX(calc_lrcur,21))*100) -> 0.38910887 | X32: =IF($T32="","",INDEX(calc_arate_p,21)) -> 1 | Y32: =IF($T32="","",INDEX(calc_amod_p,21)) -> 1.0065728
A33: MM | B33: AZ | C33: 0.576 | D33: current | E33: 0.05 | F33: 0.92 | G33: 0.91 | H33: 46295 | I33: 0.9 | L33: 7200 | N33: 1 | P33: ON | T33: =IF(OR($A33="",$B33=""),"",$A33&"|"&$B33) -> MM|AZ | V33: =IF($T33="","",INDEX(calc_cylr_p,22)) -> 0.57071568 | W33: =IF($T33="","",(INDEX(calc_cylr_p,22)-INDEX(calc_lrcur,22))*100) -> -0.52843248 | X33: =IF($T33="","",INDEX(calc_arate_p,22)) -> 0.97575609 | Y33: =IF($T33="","",INDEX(calc_amod_p,22)) -> 1.0154442
A34: MM | B34: CO | C34: 0.56 | D34: proposed | E34: 0.08 | F34: 0.92 | G34: 0.91 | H34: 46295 | I34: 0.915 | L34: 17600 | M34: 0.01 | N34: 1 | P34: ON | T34: =IF(OR($A34="",$B34=""),"",$A34&"|"&$B34) -> MM|CO | V34: =IF($T34="","",INDEX(calc_cylr_p,23)) -> 0.61272625 | W34: =IF($T34="","",(INDEX(calc_cylr_p,23)-INDEX(calc_lrcur,23))*100) -> 0.79262522 | X34: =IF($T34="","",INDEX(calc_arate_p,23)) -> 1.0042918 | Y34: =IF($T34="","",INDEX(calc_amod_p,23)) -> 1.0087761
A35: MM | B35: DE | C35: 0.588 | D35: current | E35: 0.05 | F35: 0.92 | G35: 0.91 | H35: 46295 | I35: 0.93 | L35: 14400 | N35: 1.02 | O35: Commission timing | P35: ON | T35: =IF(OR($A35="",$B35=""),"",$A35&"|"&$B35) -> MM|DE | V35: =IF($T35="","",INDEX(calc_cylr_p,24)) -> 0.59431848 | W35: =IF($T35="","",(INDEX(calc_cylr_p,24)-INDEX(calc_lrcur,24))*100) -> 0.63184809 | X35: =IF($T35="","",INDEX(calc_arate_p,24)) -> 0.98875688 | Y35: =IF($T35="","",INDEX(calc_amod_p,24)) -> 1.002195
A36: MM | B36: FL | C36: 0.572 | D36: current | E36: 0.05 | F36: 0.92 | G36: 0.91 | H36: 46295 | I36: 0.91 | L36: 11200 | N36: 1 | P36: ON | T36: =IF(OR($A36="",$B36=""),"",$A36&"|"&$B36) -> MM|FL | V36: =IF($T36="","",INDEX(calc_cylr_p,25)) -> 0.56507959 | W36: =IF($T36="","",(INDEX(calc_cylr_p,25)-INDEX(calc_lrcur,25))*100) -> -0.69204051 | X36: =IF($T36="","",INDEX(calc_arate_p,25)) -> 0.97716333 | Y36: =IF($T36="","",INDEX(calc_amod_p,25)) -> 1.010989
A37: MM | B37: GA | C37: 0.6 | D37: current | E37: 0.05 | F37: 0.92 | G37: 0.91 | H37: 46295 | I37: 0.925 | L37: 8000 | N37: 1 | P37: ON | T37: =IF(OR($A37="",$B37=""),"",$A37&"|"&$B37) -> MM|GA | V37: =IF($T37="","",INDEX(calc_cylr_p,26)) -> 0.59469816 | W37: =IF($T37="","",(INDEX(calc_cylr_p,26)-INDEX(calc_lrcur,26))*100) -> -0.53018435 | X37: =IF($T37="","",INDEX(calc_arate_p,26)) -> 0.98684211 | Y37: =IF($T37="","",INDEX(calc_amod_p,26)) -> 1.0043791
A38: MM | B38: IA | C38: 0.584 | D38: current | E38: 0.05 | F38: 0.92 | G38: 0.91 | H38: 46295 | I38: 0.905 | L38: 18400 | N38: 1 | P38: ON | T38: =IF(OR($A38="",$B38=""),"",$A38&"|"&$B38) -> MM|IA | V38: =IF($T38="","",INDEX(calc_cylr_p,27)) -> 0.59171563 | W38: =IF($T38="","",(INDEX(calc_cylr_p,27)-INDEX(calc_lrcur,27))*100) -> 0.77156256 | X38: =IF($T38="","",INDEX(calc_arate_p,27)) -> 1 | Y38: =IF($T38="","",INDEX(calc_amod_p,27)) -> 1.0132117
A39: MM | B39: IL | C39: 0.568 | D39: current | E39: 0.05 | F39: 0.92 | G39: 0.91 | H39: 46295 | I39: 0.92 | L39: 15200 | N39: 1 | P39: ON | T39: =IF(OR($A39="",$B39=""),"",$A39&"|"&$B39) -> MM|IL | V39: =IF($T39="","",INDEX(calc_cylr_p,28)) -> 0.57173334 | W39: =IF($T39="","",(INDEX(calc_cylr_p,28)-INDEX(calc_lrcur,28))*100) -> 0.37333418 | X39: =IF($T39="","",INDEX(calc_arate_p,28)) -> 1 | Y39: =IF($T39="","",INDEX(calc_amod_p,28)) -> 1.0065728
A40: MM | B40: IN | C40: 0.596 | D40: current | E40: 0.05 | F40: 0.92 | G40: 0.91 | H40: 46295 | I40: 0.9 | L40: 12000 | N40: 1 | P40: ON | T40: =IF(OR($A40="",$B40=""),"",$A40&"|"&$B40) -> MM|IN | V40: =IF($T40="","",INDEX(calc_cylr_p,29)) -> 0.60520472 | W40: =IF($T40="","",(INDEX(calc_cylr_p,29)-INDEX(calc_lrcur,29))*100) -> 0.92047189 | X40: =IF($T40="","",INDEX(calc_arate_p,29)) -> 1 | Y40: =IF($T40="","",INDEX(calc_amod_p,29)) -> 1.0154442
A41: MM | B41: KY | C41: 0.58 | D41: current | E41: 0.05 | F41: 0.92 | G41: 0.91 | H41: 46295 | I41: 0.915 | L41: 8800 | N41: 1 | P41: ON | T41: =IF(OR($A41="",$B41=""),"",$A41&"|"&$B41) -> MM|KY | V41: =IF($T41="","",INDEX(calc_cylr_p,30)) -> 0.58363104 | W41: =IF($T41="","",(INDEX(calc_cylr_p,30)-INDEX(calc_lrcur,30))*100) -> 0.36310399 | X41: =IF($T41="","",INDEX(calc_arate_p,30)) -> 0.99750623 | Y41: =IF($T41="","",INDEX(calc_amod_p,30)) -> 1.0087761
A42: MM | B42: MD | C42: 0.564 | D42: current | E42: 0.05 | F42: 0.92 | G42: 0.91 | H42: 46295 | I42: 0.93 | L42: 19200 | N42: 1 | P42: ON | T42: =IF(OR($A42="",$B42=""),"",$A42&"|"&$B42) -> MM|MD | V42: =IF($T42="","",INDEX(calc_cylr_p,31)) -> 0.56523796 | W42: =IF($T42="","",(INDEX(calc_cylr_p,31)-INDEX(calc_lrcur,31))*100) -> 0.12379649 | X42: =IF($T42="","",INDEX(calc_arate_p,31)) -> 1 | Y42: =IF($T42="","",INDEX(calc_amod_p,31)) -> 1.002195
...

Sheet Rate Log
A1: Rate Change Log — Inland Marine
A2: One row per rate change per BU x state. Columns A:H are one contiguous paste block; planned rows earn filed % x achievement %. The live columns on the right show the impact of every edit on the same row.
A3: Go to: | C3: =HYPERLINK("#Control!A1","Control") -> Control | E3: =HYPERLINK("#Inputs!A1","Inputs") -> Inputs | G3: =HYPERLINK("#Bridge!A1","Bridge") -> Bridge | I3: =HYPERLINK("#Walkthrough!A1","Walkthrough") -> Walkthrough | K3: =HYPERLINK("#Checks!A1","Checks") -> Checks
A4: SAMPLE DATA: replace the populated rows with your own log. Do not insert or delete rows — spare capacity is provided below the sample.
J5: engine helpers (formulas — do not edit) | V5: live results (formulas — do not edit)
A6: BU | B6: State | C6: Effective date | D6: Filed chg % | E6: Status (taken / planned) | F6: In indication? (Y/N) | G6: Achievement % (planned) | H6: Comment | J6: Key | K6: r_eff | L6: ln(1+r) | M6: Eff month | N6: Days on/after | O6: Earlier cnt | P6: Same cnt | Q6: First? | R6: Dup month? | S6: Seq | T6: 1st planned | U6: 1st taken | V6: This combo's CY plan LR | W6: Chg vs projected (pts) | X6: % of plan yr this action earns (selected combo) | Y6: Warnings
A7: ABD | B7: AZ | C7: 45839 | D7: 0.04 | E7: taken | F7: Y | H7: Worked example (§9) | J7: =IF(OR($A7="",$B7=""),"",$A7&"|"&$B7) -> ABD|AZ | K7: =IF($C7="","",$D7*IF($E7="planned",IF($G7="",1,$G7),1)) -> 0.04 | L7: =IF($C7="",0,IF(1+$K7>0,LN(1+$K7),0)) -> 0.039220713 | M7: =IF($C7="","",DATE(YEAR($C7),MONTH($C7),1)) -> 45839 | N7: =IF($C7="",0,EOMONTH($C7,0)-$C7+1) -> 31 | O7: =IF($C7="",0,COUNTIFS(rl_key,$J7,rl_effmonth,$M7,rl_eff,"<"&$C7)) -> 0 | P7: =IF($C7="",0,COUNTIFS($J$7:$J7,$J7,$M$7:$M7,$M7,$C$7:$C7,$C7)) -> 1 | Q7: =IF($C7="",0,IF(AND($O7=0,$P7=1),1,0)) -> 1 | R7: =IF($C7="",0,IF(COUNTIFS(rl_key,$J7,rl_effmonth,$M7)>1,1,0)) -> 0 | S7: =IF($C7="",0,COUNTIFS(rl_key,$J7,rl_eff,"<"&$C7)+COUNTIFS($J$7:$J7,$J7,$C$7:$C7,$C7)) -> 1 | T7: =IF(OR($C7="",$E7<>"planned",$C7<DATE(nr_PlanYear,1,1),$C7>DATE(nr_PlanYear,12,31)),0,IF(AND(COUNTIFS(rl_key,$J7,rl_status,"planned",rl_eff,">="&DATE(nr_PlanYear,1,1),rl_eff,"<"&$C7)=0,COUNTIFS($J$7:$J7,$J7,$E$7:$E7,"planned",$C$7:$C7,$C7)=1),1,0)) -> 0 | U7: =IF(OR($C7="",$E7<>"taken"),0,IF(AND(COUNTIFS(rl_key,$J7,rl_effmonth,$M7,rl_eff,"<"&$C7,rl_status,"taken")=0,COUNTIFS($J$7:$J7,$J7,$M$7:$M7,$M7,$C$7:$C7,$C7,$E$7:$E7,"taken")=1),1,0)) -> 1 | V7: =IF($J7="","",IF(COUNTIF(lr_key,$J7)=0,"not in tbl_LR",INDEX(calc_cylr_p,MATCH($J7,lr_key,0)))) -> 0.61816314 | W7: =IF(OR($J7="",COUNTIF(lr_key,$J7)=0),"",(INDEX(calc_cylr_p,MATCH($J7,lr_key,0))-INDEX(calc_lrcur,MATCH($J7,lr_key,0)))*100) -> -3.1836864 | X7: =IF(OR($C7="",$J7<>nr_SelKey),"",(SUMPRODUCT(('Rate Engine'!$G$17:$G$64>YEAR($C7)*12+MONTH($C7)-1)*'Rate Engine'!$H$17:$H$64,'Rate Engine'!$Q$17:$Q$64)+(EOMONTH($C7,0)-$C7+1)/DAY(EOMONTH($C7,0))*SUMPRODUCT(('Rate Engine'!$G$17:$G$64=YEAR($C7)*12+MONTH($C7)-1)*'Rate Engine'!$H$17:$H$64,'Rate Engine'!$Q$17:$Q$64))/SUMPRODUCT('Rate Engine'!$H$17:$H$64,'Rate Engine'!$Q$17:$Q$64)) -> 1 | Y7: =IF($C7="","",IF(AND($E7="taken",$G7<>"",$G7<>1),"achievement ignored — restate Filed %",""))
A8: ABD | B8: AZ | C8: 46204 | D8: 0.06 | E8: taken | F8: Y | H8: Worked example (§9) | J8: =IF(OR($A8="",$B8=""),"",$A8&"|"&$B8) -> ABD|AZ | K8: =IF($C8="","",$D8*IF($E8="planned",IF($G8="",1,$G8),1)) -> 0.06 | L8: =IF($C8="",0,IF(1+$K8>0,LN(1+$K8),0)) -> 0.058268908 | M8: =IF($C8="","",DATE(YEAR($C8),MONTH($C8),1)) -> 46204 | N8: =IF($C8="",0,EOMONTH($C8,0)-$C8+1) -> 31 | O8: =IF($C8="",0,COUNTIFS(rl_key,$J8,rl_effmonth,$M8,rl_eff,"<"&$C8)) -> 0 | P8: =IF($C8="",0,COUNTIFS($J$7:$J8,$J8,$M$7:$M8,$M8,$C$7:$C8,$C8)) -> 1 | Q8: =IF($C8="",0,IF(AND($O8=0,$P8=1),1,0)) -> 1 | R8: =IF($C8="",0,IF(COUNTIFS(rl_key,$J8,rl_effmonth,$M8)>1,1,0)) -> 0 | S8: =IF($C8="",0,COUNTIFS(rl_key,$J8,rl_eff,"<"&$C8)+COUNTIFS($J$7:$J8,$J8,$C$7:$C8,$C8)) -> 2 | T8: =IF(OR($C8="",$E8<>"planned",$C8<DATE(nr_PlanYear,1,1),$C8>DATE(nr_PlanYear,12,31)),0,IF(AND(COUNTIFS(rl_key,$J8,rl_status,"planned",rl_eff,">="&DATE(nr_PlanYear,1,1),rl_eff,"<"&$C8)=0,COUNTIFS($J$7:$J8,$J8,$E$7:$E8,"planned",$C$7:$C8,$C8)=1),1,0)) -> 0 | U8: =IF(OR($C8="",$E8<>"taken"),0,IF(AND(COUNTIFS(rl_key,$J8,rl_effmonth,$M8,rl_eff,"<"&$C8,rl_status,"taken")=0,COUNTIFS($J$7:$J8,$J8,$M$7:$M8,$M8,$C$7:$C8,$C8,$E$7:$E8,"taken")=1),1,0)) -> 1 | V8: =IF($J8="","",IF(COUNTIF(lr_key,$J8)=0,"not in tbl_LR",INDEX(calc_cylr_p,MATCH($J8,lr_key,0)))) -> 0.61816314 | W8: =IF(OR($J8="",COUNTIF(lr_key,$J8)=0),"",(INDEX(calc_cylr_p,MATCH($J8,lr_key,0))-INDEX(calc_lrcur,MATCH($J8,lr_key,0)))*100) -> -3.1836864 | X8: =IF(OR($C8="",$J8<>nr_SelKey),"",(SUMPRODUCT(('Rate Engine'!$G$17:$G$64>YEAR($C8)*12+MONTH($C8)-1)*'Rate Engine'!$H$17:$H$64,'Rate Engine'!$Q$17:$Q$64)+(EOMONTH($C8,0)-$C8+1)/DAY(EOMONTH($C8,0))*SUMPRODUCT(('Rate Engine'!$G$17:$G$64=YEAR($C8)*12+MONTH($C8)-1)*'Rate Engine'!$H$17:$H$64,'Rate Engine'!$Q$17:$Q$64))/SUMPRODUCT('Rate Engine'!$H$17:$H$64,'Rate Engine'!$Q$17:$Q$64)) -> 1 | Y8: =IF($C8="","",IF(AND($E8="taken",$G8<>"",$G8<>1),"achievement ignored — restate Filed %",""))
A9: ABD | B9: AZ | C9: 46478 | D9: 0.05 | E9: planned | F9: N | G9: 1 | H9: Planned spring increase | J9: =IF(OR($A9="",$B9=""),"",$A9&"|"&$B9) -> ABD|AZ | K9: =IF($C9="","",$D9*IF($E9="planned",IF($G9="",1,$G9),1)) -> 0.05 | L9: =IF($C9="",0,IF(1+$K9>0,LN(1+$K9),0)) -> 0.048790164 | M9: =IF($C9="","",DATE(YEAR($C9),MONTH($C9),1)) -> 46478 | N9: =IF($C9="",0,EOMONTH($C9,0)-$C9+1) -> 30 | O9: =IF($C9="",0,COUNTIFS(rl_key,$J9,rl_effmonth,$M9,rl_eff,"<"&$C9)) -> 0 | P9: =IF($C9="",0,COUNTIFS($J$7:$J9,$J9,$M$7:$M9,$M9,$C$7:$C9,$C9)) -> 1 | Q9: =IF($C9="",0,IF(AND($O9=0,$P9=1),1,0)) -> 1 | R9: =IF($C9="",0,IF(COUNTIFS(rl_key,$J9,rl_effmonth,$M9)>1,1,0)) -> 0 | S9: =IF($C9="",0,COUNTIFS(rl_key,$J9,rl_eff,"<"&$C9)+COUNTIFS($J$7:$J9,$J9,$C$7:$C9,$C9)) -> 3 | T9: =IF(OR($C9="",$E9<>"planned",$C9<DATE(nr_PlanYear,1,1),$C9>DATE(nr_PlanYear,12,31)),0,IF(AND(COUNTIFS(rl_key,$J9,rl_status,"planned",rl_eff,">="&DATE(nr_PlanYear,1,1),rl_eff,"<"&$C9)=0,COUNTIFS($J$7:$J9,$J9,$E$7:$E9,"planned",$C$7:$C9,$C9)=1),1,0)) -> 1 | U9: =IF(OR($C9="",$E9<>"taken"),0,IF(AND(COUNTIFS(rl_key,$J9,rl_effmonth,$M9,rl_eff,"<"&$C9,rl_status,"taken")=0,COUNTIFS($J$7:$J9,$J9,$M$7:$M9,$M9,$C$7:$C9,$C9,$E$7:$E9,"taken")=1),1,0)) -> 0 | V9: =IF($J9="","",IF(COUNTIF(lr_key,$J9)=0,"not in tbl_LR",INDEX(calc_cylr_p,MATCH($J9,lr_key,0)))) -> 0.61816314 | W9: =IF(OR($J9="",COUNTIF(lr_key,$J9)=0),"",(INDEX(calc_cylr_p,MATCH($J9,lr_key,0))-INDEX(calc_lrcur,MATCH($J9,lr_key,0)))*100) -> -3.1836864 | X9: =IF(OR($C9="",$J9<>nr_SelKey),"",(SUMPRODUCT(('Rate Engine'!$G$17:$G$64>YEAR($C9)*12+MONTH($C9)-1)*'Rate Engine'!$H$17:$H$64,'Rate Engine'!$Q$17:$Q$64)+(EOMONTH($C9,0)-$C9+1)/DAY(EOMONTH($C9,0))*SUMPRODUCT(('Rate Engine'!$G$17:$G$64=YEAR($C9)*12+MONTH($C9)-1)*'Rate Engine'!$H$17:$H$64,'Rate Engine'!$Q$17:$Q$64))/SUMPRODUCT('Rate Engine'!$H$17:$H$64,'Rate Engine'!$Q$17:$Q$64)) -> 0.5 | Y9: =IF($C9="","",IF(AND($E9="taken",$G9<>"",$G9<>1),"achievement ignored — restate Filed %",""))
A10: SBA | B10: IL | C10: 46204 | D10: 0.065 | E10: planned | F10: N | G10: 1 | H10: Pattern: indication's selected change entered as a planned row | J10: =IF(OR($A10="",$B10=""),"",$A10&"|"&$B10) -> SBA|IL | K10: =IF($C10="","",$D10*IF($E10="planned",IF($G10="",1,$G10),1)) -> 0.065 | L10: =IF($C10="",0,IF(1+$K10>0,LN(1+$K10),0)) -> 0.062974799 | M10: =IF($C10="","",DATE(YEAR($C10),MONTH($C10),1)) -> 46204 | N10: =IF($C10="",0,EOMONTH($C10,0)-$C10+1) -> 31 | O10: =IF($C10="",0,COUNTIFS(rl_key,$J10,rl_effmonth,$M10,rl_eff,"<"&$C10)) -> 0 | P10: =IF($C10="",0,COUNTIFS($J$7:$J10,$J10,$M$7:$M10,$M10,$C$7:$C10,$C10)) -> 1 | Q10: =IF($C10="",0,IF(AND($O10=0,$P10=1),1,0)) -> 1 | R10: =IF($C10="",0,IF(COUNTIFS(rl_key,$J10,rl_effmonth,$M10)>1,1,0)) -> 0 | S10: =IF($C10="",0,COUNTIFS(rl_key,$J10,rl_eff,"<"&$C10)+COUNTIFS($J$7:$J10,$J10,$C$7:$C10,$C10)) -> 1 | T10: =IF(OR($C10="",$E10<>"planned",$C10<DATE(nr_PlanYear,1,1),$C10>DATE(nr_PlanYear,12,31)),0,IF(AND(COUNTIFS(rl_key,$J10,rl_status,"planned",rl_eff,">="&DATE(nr_PlanYear,1,1),rl_eff,"<"&$C10)=0,COUNTIFS($J$7:$J10,$J10,$E$7:$E10,"planned",$C$7:$C10,$C10)=1),1,0)) -> 0 | U10: =IF(OR($C10="",$E10<>"taken"),0,IF(AND(COUNTIFS(rl_key,$J10,rl_effmonth,$M10,rl_eff,"<"&$C10,rl_status,"taken")=0,COUNTIFS($J$7:$J10,$J10,$M$7:$M10,$M10,$C$7:$C10,$C10,$E$7:$E10,"taken")=1),1,0)) -> 0 | V10: =IF($J10="","",IF(COUNTIF(lr_key,$J10)=0,"not in tbl_LR",INDEX(calc_cylr_p,MATCH($J10,lr_key,0)))) -> 0.55196104 | W10: =IF(OR($J10="",COUNTIF(lr_key,$J10)=0),"",(INDEX(calc_cylr_p,MATCH($J10,lr_key,0))-INDEX(calc_lrcur,MATCH($J10,lr_key,0)))*100) -> -3.2038961 | X10: =IF(OR($C10="",$J10<>nr_SelKey),"",(SUMPRODUCT(('Rate Engine'!$G$17:$G$64>YEAR($C10)*12+MONTH($C10)-1)*'Rate Engine'!$H$17:$H$64,'Rate Engine'!$Q$17:$Q$64)+(EOMONTH($C10,0)-$C10+1)/DAY(EOMONTH($C10,0))*SUMPRODUCT(('Rate Engine'!$G$17:$G$64=YEAR($C10)*12+MONTH($C10)-1)*'Rate Engine'!$H$17:$H$64,'Rate Engine'!$Q$17:$Q$64))/SUMPRODUCT('Rate Engine'!$H$17:$H$64,'Rate Engine'!$Q$17:$Q$64)) | Y10: =IF($C10="","",IF(AND($E10="taken",$G10<>"",$G10<>1),"achievement ignored — restate Filed %",""))
A11: MM | B11: DE | C11: 46113 | D11: 0.05 | E11: taken | F11: Y | J11: =IF(OR($A11="",$B11=""),"",$A11&"|"&$B11) -> MM|DE | K11: =IF($C11="","",$D11*IF($E11="planned",IF($G11="",1,$G11),1)) -> 0.05 | L11: =IF($C11="",0,IF(1+$K11>0,LN(1+$K11),0)) -> 0.048790164 | M11: =IF($C11="","",DATE(YEAR($C11),MONTH($C11),1)) -> 46113 | N11: =IF($C11="",0,EOMONTH($C11,0)-$C11+1) -> 30 | O11: =IF($C11="",0,COUNTIFS(rl_key,$J11,rl_effmonth,$M11,rl_eff,"<"&$C11)) -> 0 | P11: =IF($C11="",0,COUNTIFS($J$7:$J11,$J11,$M$7:$M11,$M11,$C$7:$C11,$C11)) -> 1 | Q11: =IF($C11="",0,IF(AND($O11=0,$P11=1),1,0)) -> 1 | R11: =IF($C11="",0,IF(COUNTIFS(rl_key,$J11,rl_effmonth,$M11)>1,1,0)) -> 0 | S11: =IF($C11="",0,COUNTIFS(rl_key,$J11,rl_eff,"<"&$C11)+COUNTIFS($J$7:$J11,$J11,$C$7:$C11,$C11)) -> 1 | T11: =IF(OR($C11="",$E11<>"planned",$C11<DATE(nr_PlanYear,1,1),$C11>DATE(nr_PlanYear,12,31)),0,IF(AND(COUNTIFS(rl_key,$J11,rl_status,"planned",rl_eff,">="&DATE(nr_PlanYear,1,1),rl_eff,"<"&$C11)=0,COUNTIFS($J$7:$J11,$J11,$E$7:$E11,"planned",$C$7:$C11,$C11)=1),1,0)) -> 0 | U11: =IF(OR($C11="",$E11<>"taken"),0,IF(AND(COUNTIFS(rl_key,$J11,rl_effmonth,$M11,rl_eff,"<"&$C11,rl_status,"taken")=0,COUNTIFS($J$7:$J11,$J11,$M$7:$M11,$M11,$C$7:$C11,$C11,$E$7:$E11,"taken")=1),1,0)) -> 1 | V11: =IF($J11="","",IF(COUNTIF(lr_key,$J11)=0,"not in tbl_LR",INDEX(calc_cylr_p,MATCH($J11,lr_key,0)))) -> 0.59431848 | W11: =IF(OR($J11="",COUNTIF(lr_key,$J11)=0),"",(INDEX(calc_cylr_p,MATCH($J11,lr_key,0))-INDEX(calc_lrcur,MATCH($J11,lr_key,0)))*100) -> 0.63184809 | X11: =IF(OR($C11="",$J11<>nr_SelKey),"",(SUMPRODUCT(('Rate Engine'!$G$17:$G$64>YEAR($C11)*12+MONTH($C11)-1)*'Rate Engine'!$H$17:$H$64,'Rate Engine'!$Q$17:$Q$64)+(EOMONTH($C11,0)-$C11+1)/DAY(EOMONTH($C11,0))*SUMPRODUCT(('Rate Engine'!$G$17:$G$64=YEAR($C11)*12+MONTH($C11)-1)*'Rate Engine'!$H$17:$H$64,'Rate Engine'!$Q$17:$Q$64))/SUMPRODUCT('Rate Engine'!$H$17:$H$64,'Rate Engine'!$Q$17:$Q$64)) | Y11: =IF($C11="","",IF(AND($E11="taken",$G11<>"",$G11<>1),"achievement ignored — restate Filed %",""))
A12: MM | B12: DE | C12: 46522 | D12: 0.03 | E12: planned | F12: N | G12: 1 | H12: Mid-month effective date example | J12: =IF(OR($A12="",$B12=""),"",$A12&"|"&$B12) -> MM|DE | K12: =IF($C12="","",$D12*IF($E12="planned",IF($G12="",1,$G12),1)) -> 0.03 | L12: =IF($C12="",0,IF(1+$K12>0,LN(1+$K12),0)) -> 0.029558802 | M12: =IF($C12="","",DATE(YEAR($C12),MONTH($C12),1)) -> 46508 | N12: =IF($C12="",0,EOMONTH($C12,0)-$C12+1) -> 17 | O12: =IF($C12="",0,COUNTIFS(rl_key,$J12,rl_effmonth,$M12,rl_eff,"<"&$C12)) -> 0 | P12: =IF($C12="",0,COUNTIFS($J$7:$J12,$J12,$M$7:$M12,$M12,$C$7:$C12,$C12)) -> 1 | Q12: =IF($C12="",0,IF(AND($O12=0,$P12=1),1,0)) -> 1 | R12: =IF($C12="",0,IF(COUNTIFS(rl_key,$J12,rl_effmonth,$M12)>1,1,0)) -> 0 | S12: =IF($C12="",0,COUNTIFS(rl_key,$J12,rl_eff,"<"&$C12)+COUNTIFS($J$7:$J12,$J12,$C$7:$C12,$C12)) -> 2 | T12: =IF(OR($C12="",$E12<>"planned",$C12<DATE(nr_PlanYear,1,1),$C12>DATE(nr_PlanYear,12,31)),0,IF(AND(COUNTIFS(rl_key,$J12,rl_status,"planned",rl_eff,">="&DATE(nr_PlanYear,1,1),rl_eff,"<"&$C12)=0,COUNTIFS($J$7:$J12,$J12,$E$7:$E12,"planned",$C$7:$C12,$C12)=1),1,0)) -> 1 | U12: =IF(OR($C12="",$E12<>"taken"),0,IF(AND(COUNTIFS(rl_key,$J12,rl_effmonth,$M12,rl_eff,"<"&$C12,rl_status,"taken")=0,COUNTIFS($J$7:$J12,$J12,$M$7:$M12,$M12,$C$7:$C12,$C12,$E$7:$E12,"taken")=1),1,0)) -> 0 | V12: =IF($J12="","",IF(COUNTIF(lr_key,$J12)=0,"not in tbl_LR",INDEX(calc_cylr_p,MATCH($J12,lr_key,0)))) -> 0.59431848 | W12: =IF(OR($J12="",COUNTIF(lr_key,$J12)=0),"",(INDEX(calc_cylr_p,MATCH($J12,lr_key,0))-INDEX(calc_lrcur,MATCH($J12,lr_key,0)))*100) -> 0.63184809 | X12: =IF(OR($C12="",$J12<>nr_SelKey),"",(SUMPRODUCT(('Rate Engine'!$G$17:$G$64>YEAR($C12)*12+MONTH($C12)-1)*'Rate Engine'!$H$17:$H$64,'Rate Engine'!$Q$17:$Q$64)+(EOMONTH($C12,0)-$C12+1)/DAY(EOMONTH($C12,0))*SUMPRODUCT(('Rate Engine'!$G$17:$G$64=YEAR($C12)*12+MONTH($C12)-1)*'Rate Engine'!$H$17:$H$64,'Rate Engine'!$Q$17:$Q$64))/SUMPRODUCT('Rate Engine'!$H$17:$H$64,'Rate Engine'!$Q$17:$Q$64)) | Y12: =IF($C12="","",IF(AND($E12="taken",$G12<>"",$G12<>1),"achievement ignored — restate Filed %",""))
A13: MM | B13: FL | C13: 46296 | D13: 0.08 | E13: taken | F13: Y | J13: =IF(OR($A13="",$B13=""),"",$A13&"|"&$B13) -> MM|FL | K13: =IF($C13="","",$D13*IF($E13="planned",IF($G13="",1,$G13),1)) -> 0.08 | L13: =IF($C13="",0,IF(1+$K13>0,LN(1+$K13),0)) -> 0.076961041 | M13: =IF($C13="","",DATE(YEAR($C13),MONTH($C13),1)) -> 46296 | N13: =IF($C13="",0,EOMONTH($C13,0)-$C13+1) -> 31 | O13: =IF($C13="",0,COUNTIFS(rl_key,$J13,rl_effmonth,$M13,rl_eff,"<"&$C13)) -> 0 | P13: =IF($C13="",0,COUNTIFS($J$7:$J13,$J13,$M$7:$M13,$M13,$C$7:$C13,$C13)) -> 1 | Q13: =IF($C13="",0,IF(AND($O13=0,$P13=1),1,0)) -> 1 | R13: =IF($C13="",0,IF(COUNTIFS(rl_key,$J13,rl_effmonth,$M13)>1,1,0)) -> 0 | S13: =IF($C13="",0,COUNTIFS(rl_key,$J13,rl_eff,"<"&$C13)+COUNTIFS($J$7:$J13,$J13,$C$7:$C13,$C13)) -> 1 | T13: =IF(OR($C13="",$E13<>"planned",$C13<DATE(nr_PlanYear,1,1),$C13>DATE(nr_PlanYear,12,31)),0,IF(AND(COUNTIFS(rl_key,$J13,rl_status,"planned",rl_eff,">="&DATE(nr_PlanYear,1,1),rl_eff,"<"&$C13)=0,COUNTIFS($J$7:$J13,$J13,$E$7:$E13,"planned",$C$7:$C13,$C13)=1),1,0)) -> 0 | U13: =IF(OR($C13="",$E13<>"taken"),0,IF(AND(COUNTIFS(rl_key,$J13,rl_effmonth,$M13,rl_eff,"<"&$C13,rl_status,"taken")=0,COUNTIFS($J$7:$J13,$J13,$M$7:$M13,$M13,$C$7:$C13,$C13,$E$7:$E13,"taken")=1),1,0)) -> 1 | V13: =IF($J13="","",IF(COUNTIF(lr_key,$J13)=0,"not in tbl_LR",INDEX(calc_cylr_p,MATCH($J13,lr_key,0)))) -> 0.56507959 | W13: =IF(OR($J13="",COUNTIF(lr_key,$J13)=0),"",(INDEX(calc_cylr_p,MATCH($J13,lr_key,0))-INDEX(calc_lrcur,MATCH($J13,lr_key,0)))*100) -> -0.69204051 | X13: =IF(OR($C13="",$J13<>nr_SelKey),"",(SUMPRODUCT(('Rate Engine'!$G$17:$G$64>YEAR($C13)*12+MONTH($C13)-1)*'Rate Engine'!$H$17:$H$64,'Rate Engine'!$Q$17:$Q$64)+(EOMONTH($C13,0)-$C13+1)/DAY(EOMONTH($C13,0))*SUMPRODUCT(('Rate Engine'!$G$17:$G$64=YEAR($C13)*12+MONTH($C13)-1)*'Rate Engine'!$H$17:$H$64,'Rate Engine'!$Q$17:$Q$64))/SUMPRODUCT('Rate Engine'!$H$17:$H$64,'Rate Engine'!$Q$17:$Q$64)) | Y13: =IF($C13="","",IF(AND($E13="taken",$G13<>"",$G13<>1),"achievement ignored — restate Filed %",""))
A14: MM | B14: FL | C14: 46447 | D14: 0.06 | E14: planned | F14: N | G14: 0.8 | H14: 80% achievement assumed | J14: =IF(OR($A14="",$B14=""),"",$A14&"|"&$B14) -> MM|FL | K14: =IF($C14="","",$D14*IF($E14="planned",IF($G14="",1,$G14),1)) -> 0.048 | L14: =IF($C14="",0,IF(1+$K14>0,LN(1+$K14),0)) -> 0.046883586 | M14: =IF($C14="","",DATE(YEAR($C14),MONTH($C14),1)) -> 46447 | N14: =IF($C14="",0,EOMONTH($C14,0)-$C14+1) -> 31 | O14: =IF($C14="",0,COUNTIFS(rl_key,$J14,rl_effmonth,$M14,rl_eff,"<"&$C14)) -> 0 | P14: =IF($C14="",0,COUNTIFS($J$7:$J14,$J14,$M$7:$M14,$M14,$C$7:$C14,$C14)) -> 1 | Q14: =IF($C14="",0,IF(AND($O14=0,$P14=1),1,0)) -> 1 | R14: =IF($C14="",0,IF(COUNTIFS(rl_key,$J14,rl_effmonth,$M14)>1,1,0)) -> 0 | S14: =IF($C14="",0,COUNTIFS(rl_key,$J14,rl_eff,"<"&$C14)+COUNTIFS($J$7:$J14,$J14,$C$7:$C14,$C14)) -> 2 | T14: =IF(OR($C14="",$E14<>"planned",$C14<DATE(nr_PlanYear,1,1),$C14>DATE(nr_PlanYear,12,31)),0,IF(AND(COUNTIFS(rl_key,$J14,rl_status,"planned",rl_eff,">="&DATE(nr_PlanYear,1,1),rl_eff,"<"&$C14)=0,COUNTIFS($J$7:$J14,$J14,$E$7:$E14,"planned",$C$7:$C14,$C14)=1),1,0)) -> 1 | U14: =IF(OR($C14="",$E14<>"taken"),0,IF(AND(COUNTIFS(rl_key,$J14,rl_effmonth,$M14,rl_eff,"<"&$C14,rl_status,"taken")=0,COUNTIFS($J$7:$J14,$J14,$M$7:$M14,$M14,$C$7:$C14,$C14,$E$7:$E14,"taken")=1),1,0)) -> 0 | V14: =IF($J14="","",IF(COUNTIF(lr_key,$J14)=0,"not in tbl_LR",INDEX(calc_cylr_p,MATCH($J14,lr_key,0)))) -> 0.56507959 | W14: =IF(OR($J14="",COUNTIF(lr_key,$J14)=0),"",(INDEX(calc_cylr_p,MATCH($J14,lr_key,0))-INDEX(calc_lrcur,MATCH($J14,lr_key,0)))*100) -> -0.69204051 | X14: =IF(OR($C14="",$J14<>nr_SelKey),"",(SUMPRODUCT(('Rate Engine'!$G$17:$G$64>YEAR($C14)*12+MONTH($C14)-1)*'Rate Engine'!$H$17:$H$64,'Rate Engine'!$Q$17:$Q$64)+(EOMONTH($C14,0)-$C14+1)/DAY(EOMONTH($C14,0))*SUMPRODUCT(('Rate Engine'!$G$17:$G$64=YEAR($C14)*12+MONTH($C14)-1)*'Rate Engine'!$H$17:$H$64,'Rate Engine'!$Q$17:$Q$64))/SUMPRODUCT('Rate Engine'!$H$17:$H$64,'Rate Engine'!$Q$17:$Q$64)) | Y14: =IF($C14="","",IF(AND($E14="taken",$G14<>"",$G14<>1),"achievement ignored — restate Filed %",""))
A15: ABD | B15: IA | C15: 46174 | D15: 0.045 | E15: taken | F15: Y | J15: =IF(OR($A15="",$B15=""),"",$A15&"|"&$B15) -> ABD|IA | K15: =IF($C15="","",$D15*IF($E15="planned",IF($G15="",1,$G15),1)) -> 0.045 | L15: =IF($C15="",0,IF(1+$K15>0,LN(1+$K15),0)) -> 0.044016885 | M15: =IF($C15="","",DATE(YEAR($C15),MONTH($C15),1)) -> 46174 | N15: =IF($C15="",0,EOMONTH($C15,0)-$C15+1) -> 30 | O15: =IF($C15="",0,COUNTIFS(rl_key,$J15,rl_effmonth,$M15,rl_eff,"<"&$C15)) -> 0 | P15: =IF($C15="",0,COUNTIFS($J$7:$J15,$J15,$M$7:$M15,$M15,$C$7:$C15,$C15)) -> 1 | Q15: =IF($C15="",0,IF(AND($O15=0,$P15=1),1,0)) -> 1 | R15: =IF($C15="",0,IF(COUNTIFS(rl_key,$J15,rl_effmonth,$M15)>1,1,0)) -> 0 | S15: =IF($C15="",0,COUNTIFS(rl_key,$J15,rl_eff,"<"&$C15)+COUNTIFS($J$7:$J15,$J15,$C$7:$C15,$C15)) -> 1 | T15: =IF(OR($C15="",$E15<>"planned",$C15<DATE(nr_PlanYear,1,1),$C15>DATE(nr_PlanYear,12,31)),0,IF(AND(COUNTIFS(rl_key,$J15,rl_status,"planned",rl_eff,">="&DATE(nr_PlanYear,1,1),rl_eff,"<"&$C15)=0,COUNTIFS($J$7:$J15,$J15,$E$7:$E15,"planned",$C$7:$C15,$C15)=1),1,0)) -> 0 | U15: =IF(OR($C15="",$E15<>"taken"),0,IF(AND(COUNTIFS(rl_key,$J15,rl_effmonth,$M15,rl_eff,"<"&$C15,rl_status,"taken")=0,COUNTIFS($J$7:$J15,$J15,$M$7:$M15,$M15,$C$7:$C15,$C15,$E$7:$E15,"taken")=1),1,0)) -> 1 | V15: =IF($J15="","",IF(COUNTIF(lr_key,$J15)=0,"not in tbl_LR",INDEX(calc_cylr_p,MATCH($J15,lr_key,0)))) -> 0.56797978 | W15: =IF(OR($J15="",COUNTIF(lr_key,$J15)=0),"",(INDEX(calc_cylr_p,MATCH($J15,lr_key,0))-INDEX(calc_lrcur,MATCH($J15,lr_key,0)))*100) -> -0.0020222516 | X15: =IF(OR($C15="",$J15<>nr_SelKey),"",(SUMPRODUCT(('Rate Engine'!$G$17:$G$64>YEAR($C15)*12+MONTH($C15)-1)*'Rate Engine'!$H$17:$H$64,'Rate Engine'!$Q$17:$Q$64)+(EOMONTH($C15,0)-$C15+1)/DAY(EOMONTH($C15,0))*SUMPRODUCT(('Rate Engine'!$G$17:$G$64=YEAR($C15)*12+MONTH($C15)-1)*'Rate Engine'!$H$17:$H$64,'Rate Engine'!$Q$17:$Q$64))/SUMPRODUCT('Rate Engine'!$H$17:$H$64,'Rate Engine'!$Q$17:$Q$64)) | Y15: =IF($C15="","",IF(AND($E15="taken",$G15<>"",$G15<>1),"achievement ignored — restate Filed %",""))
A16: SBA | B16: KY | C16: 46296 | D16: 0.1 | E16: taken | F16: N | H16: Net-selection showcase: fall filing (after the indication) feeds the +10% net target | J16: =IF(OR($A16="",$B16=""),"",$A16&"|"&$B16) -> SBA|KY | K16: =IF($C16="","",$D16*IF($E16="planned",IF($G16="",1,$G16),1)) -> 0.1 | L16: =IF($C16="",0,IF(1+$K16>0,LN(1+$K16),0)) -> 0.09531018 | M16: =IF($C16="","",DATE(YEAR($C16),MONTH($C16),1)) -> 46296 | N16: =IF($C16="",0,EOMONTH($C16,0)-$C16+1) -> 31 | O16: =IF($C16="",0,COUNTIFS(rl_key,$J16,rl_effmonth,$M16,rl_eff,"<"&$C16)) -> 0 | P16: =IF($C16="",0,COUNTIFS($J$7:$J16,$J16,$M$7:$M16,$M16,$C$7:$C16,$C16)) -> 1 | Q16: =IF($C16="",0,IF(AND($O16=0,$P16=1),1,0)) -> 1 | R16: =IF($C16="",0,IF(COUNTIFS(rl_key,$J16,rl_effmonth,$M16)>1,1,0)) -> 0 | S16: =IF($C16="",0,COUNTIFS(rl_key,$J16,rl_eff,"<"&$C16)+COUNTIFS($J$7:$J16,$J16,$C$7:$C16,$C16)) -> 1 | T16: =IF(OR($C16="",$E16<>"planned",$C16<DATE(nr_PlanYear,1,1),$C16>DATE(nr_PlanYear,12,31)),0,IF(AND(COUNTIFS(rl_key,$J16,rl_status,"planned",rl_eff,">="&DATE(nr_PlanYear,1,1),rl_eff,"<"&$C16)=0,COUNTIFS($J$7:$J16,$J16,$E$7:$E16,"planned",$C$7:$C16,$C16)=1),1,0)) -> 0 | U16: =IF(OR($C16="",$E16<>"taken"),0,IF(AND(COUNTIFS(rl_key,$J16,rl_effmonth,$M16,rl_eff,"<"&$C16,rl_status,"taken")=0,COUNTIFS($J$7:$J16,$J16,$M$7:$M16,$M16,$C$7:$C16,$C16,$E$7:$E16,"taken")=1),1,0)) -> 1 | V16: =IF($J16="","",IF(COUNTIF(lr_key,$J16)=0,"not in tbl_LR",INDEX(calc_cylr_p,MATCH($J16,lr_key,0)))) -> 0.54805985 | W16: =IF(OR($J16="",COUNTIF(lr_key,$J16)=0),"",(INDEX(calc_cylr_p,MATCH($J16,lr_key,0))-INDEX(calc_lrcur,MATCH($J16,lr_key,0)))*100) -> -4.7940154 | X16: =IF(OR($C16="",$J16<>nr_SelKey),"",(SUMPRODUCT(('Rate Engine'!$G$17:$G$64>YEAR($C16)*12+MONTH($C16)-1)*'Rate Engine'!$H$17:$H$64,'Rate Engine'!$Q$17:$Q$64)+(EOMONTH($C16,0)-$C16+1)/DAY(EOMONTH($C16,0))*SUMPRODUCT(('Rate Engine'!$G$17:$G$64=YEAR($C16)*12+MONTH($C16)-1)*'Rate Engine'!$H$17:$H$64,'Rate Engine'!$Q$17:$Q$64))/SUMPRODUCT('Rate Engine'!$H$17:$H$64,'Rate Engine'!$Q$17:$Q$64)) | Y16: =IF($C16="","",IF(AND($E16="taken",$G16<>"",$G16<>1),"achievement ignored — restate Filed %",""))
A17: SBA | B17: KY | C17: 46478 | D17: 0.04 | E17: planned | F17: N | G17: 1 | H17: Planned filing the net-delivery default picks up | J17: =IF(OR($A17="",$B17=""),"",$A17&"|"&$B17) -> SBA|KY | K17: =IF($C17="","",$D17*IF($E17="planned",IF($G17="",1,$G17),1)) -> 0.04 | L17: =IF($C17="",0,IF(1+$K17>0,LN(1+$K17),0)) -> 0.039220713 | M17: =IF($C17="","",DATE(YEAR($C17),MONTH($C17),1)) -> 46478 | N17: =IF($C17="",0,EOMONTH($C17,0)-$C17+1) -> 30 | O17: =IF($C17="",0,COUNTIFS(rl_key,$J17,rl_effmonth,$M17,rl_eff,"<"&$C17)) -> 0 | P17: =IF($C17="",0,COUNTIFS($J$7:$J17,$J17,$M$7:$M17,$M17,$C$7:$C17,$C17)) -> 1 | Q17: =IF($C17="",0,IF(AND($O17=0,$P17=1),1,0)) -> 1 | R17: =IF($C17="",0,IF(COUNTIFS(rl_key,$J17,rl_effmonth,$M17)>1,1,0)) -> 0 | S17: =IF($C17="",0,COUNTIFS(rl_key,$J17,rl_eff,"<"&$C17)+COUNTIFS($J$7:$J17,$J17,$C$7:$C17,$C17)) -> 2 | T17: =IF(OR($C17="",$E17<>"planned",$C17<DATE(nr_PlanYear,1,1),$C17>DATE(nr_PlanYear,12,31)),0,IF(AND(COUNTIFS(rl_key,$J17,rl_status,"planned",rl_eff,">="&DATE(nr_PlanYear,1,1),rl_eff,"<"&$C17)=0,COUNTIFS($J$7:$J17,$J17,$E$7:$E17,"planned",$C$7:$C17,$C17)=1),1,0)) -> 1 | U17: =IF(OR($C17="",$E17<>"taken"),0,IF(AND(COUNTIFS(rl_key,$J17,rl_effmonth,$M17,rl_eff,"<"&$C17,rl_status,"taken")=0,COUNTIFS($J$7:$J17,$J17,$M$7:$M17,$M17,$C$7:$C17,$C17,$E$7:$E17,"taken")=1),1,0)) -> 0 | V17: =IF($J17="","",IF(COUNTIF(lr_key,$J17)=0,"not in tbl_LR",INDEX(calc_cylr_p,MATCH($J17,lr_key,0)))) -> 0.54805985 | W17: =IF(OR($J17="",COUNTIF(lr_key,$J17)=0),"",(INDEX(calc_cylr_p,MATCH($J17,lr_key,0))-INDEX(calc_lrcur,MATCH($J17,lr_key,0)))*100) -> -4.7940154 | X17: =IF(OR($C17="",$J17<>nr_SelKey),"",(SUMPRODUCT(('Rate Engine'!$G$17:$G$64>YEAR($C17)*12+MONTH($C17)-1)*'Rate Engine'!$H$17:$H$64,'Rate Engine'!$Q$17:$Q$64)+(EOMONTH($C17,0)-$C17+1)/DAY(EOMONTH($C17,0))*SUMPRODUCT(('Rate Engine'!$G$17:$G$64=YEAR($C17)*12+MONTH($C17)-1)*'Rate Engine'!$H$17:$H$64,'Rate Engine'!$Q$17:$Q$64))/SUMPRODUCT('Rate Engine'!$H$17:$H$64,'Rate Engine'!$Q$17:$Q$64)) | Y17: =IF($C17="","",IF(AND($E17="taken",$G17<>"",$G17<>1),"achievement ignored — restate Filed %",""))
A18: ABD | B18: CO | C18: 46054 | D18: 0.03 | E18: taken | F18: Y | J18: =IF(OR($A18="",$B18=""),"",$A18&"|"&$B18) -> ABD|CO | K18: =IF($C18="","",$D18*IF($E18="planned",IF($G18="",1,$G18),1)) -> 0.03 | L18: =IF($C18="",0,IF(1+$K18>0,LN(1+$K18),0)) -> 0.029558802 | M18: =IF($C18="","",DATE(YEAR($C18),MONTH($C18),1)) -> 46054 | N18: =IF($C18="",0,EOMONTH($C18,0)-$C18+1) -> 28 | O18: =IF($C18="",0,COUNTIFS(rl_key,$J18,rl_effmonth,$M18,rl_eff,"<"&$C18)) -> 0 | P18: =IF($C18="",0,COUNTIFS($J$7:$J18,$J18,$M$7:$M18,$M18,$C$7:$C18,$C18)) -> 1 | Q18: =IF($C18="",0,IF(AND($O18=0,$P18=1),1,0)) -> 1 | R18: =IF($C18="",0,IF(COUNTIFS(rl_key,$J18,rl_effmonth,$M18)>1,1,0)) -> 0 | S18: =IF($C18="",0,COUNTIFS(rl_key,$J18,rl_eff,"<"&$C18)+COUNTIFS($J$7:$J18,$J18,$C$7:$C18,$C18)) -> 1 | T18: =IF(OR($C18="",$E18<>"planned",$C18<DATE(nr_PlanYear,1,1),$C18>DATE(nr_PlanYear,12,31)),0,IF(AND(COUNTIFS(rl_key,$J18,rl_status,"planned",rl_eff,">="&DATE(nr_PlanYear,1,1),rl_eff,"<"&$C18)=0,COUNTIFS($J$7:$J18,$J18,$E$7:$E18,"planned",$C$7:$C18,$C18)=1),1,0)) -> 0 | U18: =IF(OR($C18="",$E18<>"taken"),0,IF(AND(COUNTIFS(rl_key,$J18,rl_effmonth,$M18,rl_eff,"<"&$C18,rl_status,"taken")=0,COUNTIFS($J$7:$J18,$J18,$M$7:$M18,$M18,$C$7:$C18,$C18,$E$7:$E18,"taken")=1),1,0)) -> 1 | V18: =IF($J18="","",IF(COUNTIF(lr_key,$J18)=0,"not in tbl_LR",INDEX(calc_cylr_p,MATCH($J18,lr_key,0)))) -> 0.57775356 | W18: =IF(OR($J18="",COUNTIF(lr_key,$J18)=0),"",(INDEX(calc_cylr_p,MATCH($J18,lr_key,0))-INDEX(calc_lrcur,MATCH($J18,lr_key,0)))*100) -> -1.0246436 | X18: =IF(OR($C18="",$J18<>nr_SelKey),"",(SUMPRODUCT(('Rate Engine'!$G$17:$G$64>YEAR($C18)*12+MONTH($C18)-1)*'Rate Engine'!$H$17:$H$64,'Rate Engine'!$Q$17:$Q$64)+(EOMONTH($C18,0)-$C18+1)/DAY(EOMONTH($C18,0))*SUMPRODUCT(('Rate Engine'!$G$17:$G$64=YEAR($C18)*12+MONTH($C18)-1)*'Rate Engine'!$H$17:$H$64,'Rate Engine'!$Q$17:$Q$64))/SUMPRODUCT('Rate Engine'!$H$17:$H$64,'Rate Engine'!$Q$17:$Q$64)) | Y18: =IF($C18="","",IF(AND($E18="taken",$G18<>"",$G18<>1),"achievement ignored — restate Filed %",""))
A19: ABD | B19: CO | C19: 46419 | D19: 0.04 | E19: planned | F19: N | G19: 1 | J19: =IF(OR($A19="",$B19=""),"",$A19&"|"&$B19) -> ABD|CO | K19: =IF($C19="","",$D19*IF($E19="planned",IF($G19="",1,$G19),1)) -> 0.04 | L19: =IF($C19="",0,IF(1+$K19>0,LN(1+$K19),0)) -> 0.039220713 | M19: =IF($C19="","",DATE(YEAR($C19),MONTH($C19),1)) -> 46419 | N19: =IF($C19="",0,EOMONTH($C19,0)-$C19+1) -> 28 | O19: =IF($C19="",0,COUNTIFS(rl_key,$J19,rl_effmonth,$M19,rl_eff,"<"&$C19)) -> 0 | P19: =IF($C19="",0,COUNTIFS($J$7:$J19,$J19,$M$7:$M19,$M19,$C$7:$C19,$C19)) -> 1 | Q19: =IF($C19="",0,IF(AND($O19=0,$P19=1),1,0)) -> 1 | R19: =IF($C19="",0,IF(COUNTIFS(rl_key,$J19,rl_effmonth,$M19)>1,1,0)) -> 0 | S19: =IF($C19="",0,COUNTIFS(rl_key,$J19,rl_eff,"<"&$C19)+COUNTIFS($J$7:$J19,$J19,$C$7:$C19,$C19)) -> 2 | T19: =IF(OR($C19="",$E19<>"planned",$C19<DATE(nr_PlanYear,1,1),$C19>DATE(nr_PlanYear,12,31)),0,IF(AND(COUNTIFS(rl_key,$J19,rl_status,"planned",rl_eff,">="&DATE(nr_PlanYear,1,1),rl_eff,"<"&$C19)=0,COUNTIFS($J$7:$J19,$J19,$E$7:$E19,"planned",$C$7:$C19,$C19)=1),1,0)) -> 1 | U19: =IF(OR($C19="",$E19<>"taken"),0,IF(AND(COUNTIFS(rl_key,$J19,rl_effmonth,$M19,rl_eff,"<"&$C19,rl_status,"taken")=0,COUNTIFS($J$7:$J19,$J19,$M$7:$M19,$M19,$C$7:$C19,$C19,$E$7:$E19,"taken")=1),1,0)) -> 0 | V19: =IF($J19="","",IF(COUNTIF(lr_key,$J19)=0,"not in tbl_LR",INDEX(calc_cylr_p,MATCH($J19,lr_key,0)))) -> 0.57775356 | W19: =IF(OR($J19="",COUNTIF(lr_key,$J19)=0),"",(INDEX(calc_cylr_p,MATCH($J19,lr_key,0))-INDEX(calc_lrcur,MATCH($J19,lr_key,0)))*100) -> -1.0246436 | X19: =IF(OR($C19="",$J19<>nr_SelKey),"",(SUMPRODUCT(('Rate Engine'!$G$17:$G$64>YEAR($C19)*12+MONTH($C19)-1)*'Rate Engine'!$H$17:$H$64,'Rate Engine'!$Q$17:$Q$64)+(EOMONTH($C19,0)-$C19+1)/DAY(EOMONTH($C19,0))*SUMPRODUCT(('Rate Engine'!$G$17:$G$64=YEAR($C19)*12+MONTH($C19)-1)*'Rate Engine'!$H$17:$H$64,'Rate Engine'!$Q$17:$Q$64))/SUMPRODUCT('Rate Engine'!$H$17:$H$64,'Rate Engine'!$Q$17:$Q$64)) | Y19: =IF($C19="","",IF(AND($E19="taken",$G19<>"",$G19<>1),"achievement ignored — restate Filed %",""))
