Workbook
Name bk_bu: _book!$B$2:$B$379
Name bk_cylr_p: _book!$O$2:$O$379
Name bk_cylr_prog: _book!$Y$2:$Y$379
Name bk_ep: _book!$F$2:$F$379
Name bk_key: _book!$D$2:$D$379
Name bk_lob: _book!$A$2:$A$379
Name bk_lob_ep: 'Roll-ups'!$C$13
Name bk_lob_first: 'Roll-ups'!$C$7
Name bk_modeff: _book!$X$2:$X$379
Name bk_netmode: _book!$V$2:$V$379
Name bk_netx: _book!$W$2:$W$379
Name bk_nplanned: _book!$AD$2:$AD$379
Name bk_ntaken: _book!$AC$2:$AC$379
Name bk_overall: Checks!$C$3
Name bk_pf_first: 'Program Flow'!$B$8
Name bk_proggap: _book!$AA$2:$AA$379
Name bk_progident: _book!$AB$2:$AB$379
Name bk_srccombos: Control!$E$24
Name bk_ss_ep: 'State Summary'!$B$30
Name bk_ss_lr: 'State Summary'!$AA$30
Name bk_ss_prog: 'State Summary'!$AH$30
Name bk_state: _book!$C$2:$C$379
Name bk_ukey: _book!$E$2:$E$379
Name bkc_bu: Control!$D$8
Name bkc_lob: Control!$D$7
Name bkc_state: Control!$D$9
Name bkf_bu: Control!$B$8
Name bkf_lob: Control!$B$7
Name bkf_state: Control!$B$9

Sheet Read Me
B2: The Book — 2027 plan, every line of business
B3: Harvested 2026-08-02 00:03 from 6 workbooks | 378 combos | classic formula mode | engines frozen, filters live
B5: What this is
B6: One row per line x business unit x state, harvested from the six LOB workbooks after they were recalculated. Every per-combo number here is a VALUE copied from the file that computed it — this book cannot drift from those files, and it cannot follow them either.
B7: Every filter, weighted average and total IS live, so changing the view on Control recalculates instantly.
B8: To refresh after editing inputs: save the LOB workbook(s) in Excel, then rebuild this book (python tools/build_book.py). That is the whole loop.
B9: Regenerate a LOB workbook only for STRUCTURAL changes (new state, new capacity, new generator version) — regeneration replaces the file's contents, so carry your inputs across with 'python -m src.build_workbook --lob "<line>" --carry-forward'.
B10: The harvest refuses a workbook that was never recalculated, and refuses one whose own Checks panel is failing — see 'Source checks' on Control for what each file reported when it was read.
B12: Where to go
B13: =HYPERLINK("#Control!A1","Control") -> Control | C13: Filters (line / business unit / state), the in-view KPI band, and the source table with each file's stamp.
B14: =HYPERLINK("#'State Summary'!A1","State Summary") -> State Summary | C14: The flagship: one row per state, EP-weighted across the lines and units in view, with the full bridge chain.
B15: =HYPERLINK("#Portfolio!A1","Portfolio") -> Portfolio | C15: Every combo in the book, with Excel filters on the grid — sort and slice freely; the cells are values.
B16: =HYPERLINK("#'Roll-ups'!A1","Roll-ups") -> Roll-ups | C16: The book cut by line, by business unit, and by state, each with its mix residual.
B17: =HYPERLINK("#'Program Flow'!A1","Program Flow") -> Program Flow | C17: Month-by-month YoY rate, pricing and delivered legs across the book.
B18: =HYPERLINK("#Checks!A1","Checks") -> Checks | C18: Harvest and reconciliation checks — must read ALL CHECKS PASS.
B20: How the numbers combine
B21: Weighting is adjusted plan EP throughout, and EP x written weight for the monthly legs — the same weights the per-LOB workbooks use.
B22: An exhibit keyed by a dimension applies the OTHER filters, never its own: the per-state views honour line and business unit, the by-line roll-up honours unit and state.
B23: Weighted factor averages do not compound: the EP-weighted plan LR is not the product of the EP-weighted factors. Where both are shown, the exact weighted value is displayed and the difference is labelled Mix.
B24: Combining lines is safe for loss ratios and written-basis legs (seasonality is state-keyed; the legs are term-independent). Earning patterns are never aggregated across different policy terms.
B25: Mixing lines with different loss economics into one headline is a judgment, not an arithmetic fact — every roll-up keeps its member lines visible beside the total for that reason.
B27: Sources
B28: Property | C28: Plan_LR_Workbook_2027_Property.xlsx — 63 combos, v3.4.0, modified 2026-08-02 00:02
B29: General Liability | C29: Plan_LR_Workbook_2027_General_Liability.xlsx — 63 combos, v3.4.0, modified 2026-08-02 00:02
B30: Commercial Auto | C30: Plan_LR_Workbook_2027_Commercial_Auto.xlsx — 63 combos, v3.4.0, modified 2026-08-02 00:02
B31: Workers Comp | C31: Plan_LR_Workbook_2027_Workers_Comp.xlsx — 63 combos, v3.4.0, modified 2026-08-02 00:03
B32: Umbrella | C32: Plan_LR_Workbook_2027_Umbrella.xlsx — 63 combos, v3.4.0, modified 2026-08-02 00:03
B33: Inland Marine | C33: Plan_LR_Workbook_2027_Inland_Marine.xlsx — 63 combos, v3.4.0, modified 2026-08-02 00:03

Sheet Control
A1: The Book — every line of business at once (2027 plan)
A2: Harvested from the six LOB workbooks. The engines are frozen; every filter and total below is live. An exhibit keyed by a dimension applies the OTHER filters — the per-state views honour LOB and BU, the by-LOB roll-up honours BU and state, and the all-combo grid honours all three.
A3: Go to: | C3: =HYPERLINK("#'State Summary'!A1","State Summary") -> State Summary | E3: =HYPERLINK("#Portfolio!A1","Portfolio") -> Portfolio | G3: =HYPERLINK("#'Roll-ups'!A1","Roll-ups") -> Roll-ups | I3: =HYPERLINK("#'Program Flow'!A1","Program Flow") -> Program Flow | K3: =HYPERLINK("#Checks!A1","Checks") -> Checks | M3: =HYPERLINK("#'Read Me'!A1","Read Me") -> Read Me
A4: As of 2026-08-02 00:03 — harvested from 6 workbooks, 378 combos. Regenerate and recalculate the LOB files, then rebuild this book, to refresh.
A6: Filters
A7: Line of business | B7: All | D7: =IF(bkf_lob="All","*",bkf_lob) -> * | T7: All | U7: All | V7: All
A8: Business unit | B8: All | D8: =IF(bkf_bu="All","*",bkf_bu) -> * | T8: Property | U8: ABD | V8: AZ
A9: State | B9: All | D9: =IF(bkf_state="All","*",bkf_state) -> * | T9: General Liability | U9: MM | V9: CO
T10: Commercial Auto | U10: SBA | V10: DE
A11: In view | T11: Workers Comp | V11: FL
A12: Combos in view | C12: Adjusted plan EP | E12: CY 2027 plan loss ratio | G12: Plan LR — program basis | I12: Program vs asserted | K12: Net-target combos | T12: Umbrella | V12: GA
A13: =COUNTIFS(_book!$D$2:$D$379,"?*",_book!$A$2:$A$379,bkc_lob,_book!$B$2:$B$379,bkc_bu,_book!$C$2:$C$379,bkc_state) -> 378 | C13: =SUMIFS(_book!$F$2:$F$379,_book!$A$2:$A$379,bkc_lob,_book!$B$2:$B$379,bkc_bu,_book!$C$2:$C$379,bkc_state) -> 17085000 | E13: =IF(SUMIFS(_book!$F$2:$F$379,_book!$A$2:$A$379,bkc_lob,_book!$B$2:$B$379,bkc_bu,_book!$C$2:$C$379,bkc_state)=0,"—",SUMIFS(_book!$AO$2:$AO$379,_book!$A$2:$A$379,bkc_lob,_book!$B$2:$B$379,bkc_bu,_book!$C$2:$C$379,bkc_state)/SUMIFS(_book!$F$2:$F$379,_book!$A$2:$A$379,bkc_lob,_book!$B$2:$B$379,bkc_bu,_book!$C$2:$C$379,bkc_state)) -> 0.63839948 | G13: =IF(SUMIFS(_book!$F$2:$F$379,_book!$A$2:$A$379,bkc_lob,_book!$B$2:$B$379,bkc_bu,_book!$C$2:$C$379,bkc_state)=0,"—",SUMIFS(_book!$AT$2:$AT$379,_book!$A$2:$A$379,bkc_lob,_book!$B$2:$B$379,bkc_bu,_book!$C$2:$C$379,bkc_state)/SUMIFS(_book!$F$2:$F$379,_book!$A$2:$A$379,bkc_lob,_book!$B$2:$B$379,bkc_bu,_book!$C$2:$C$379,bkc_state)) -> 0.63832189 | I13: =IF(SUMIFS(_book!$F$2:$F$379,_book!$A$2:$A$379,bkc_lob,_book!$B$2:$B$379,bkc_bu,_book!$C$2:$C$379,bkc_state)=0,"—",(SUMIFS(_book!$AT$2:$AT$379,_book!$A$2:$A$379,bkc_lob,_book!$B$2:$B$379,bkc_bu,_book!$C$2:$C$379,bkc_state)-SUMIFS(_book!$AO$2:$AO$379,_book!$A$2:$A$379,bkc_lob,_book!$B$2:$B$379,bkc_bu,_book!$C$2:$C$379,bkc_state))/SUMIFS(_book!$F$2:$F$379,_book!$A$2:$A$379,bkc_lob,_book!$B$2:$B$379,bkc_bu,_book!$C$2:$C$379,bkc_state)*100) -> -0.0077588101 | K13: =SUMIFS(_book!$V$2:$V$379,_book!$A$2:$A$379,bkc_lob,_book!$B$2:$B$379,bkc_bu,_book!$C$2:$C$379,bkc_state) -> 6 | T13: Inland Marine | V13: IA
A14: rows passing all three filters | C14: the weight behind every average here | E14: EP-weighted across everything in view | G14: the logged program instead of any asserted net target | I14: 0.00 pts when nothing asserts a net target | K14: combos carrying an asserted net selection | V14: IL
V15: IN
A16: Sources | V16: KY
A17: Line of business | B17: Workbook | C17: Built / modified | D17: Version | E17: Combos | F17: Source checks | V17: MD
A18: Property | B18: Plan_LR_Workbook_2027_Property.xlsx | C18: 2026-08-02 00:02 | D18: 3.4.0 | E18: 63 | F18: PASS WITH 1 WARNING(S) | V18: MI
A19: General Liability | B19: Plan_LR_Workbook_2027_General_Liability.xlsx | C19: 2026-08-02 00:02 | D19: 3.4.0 | E19: 63 | F19: PASS WITH 1 WARNING(S) | V19: MN
A20: Commercial Auto | B20: Plan_LR_Workbook_2027_Commercial_Auto.xlsx | C20: 2026-08-02 00:02 | D20: 3.4.0 | E20: 63 | F20: PASS WITH 1 WARNING(S) | V20: NM
A21: Workers Comp | B21: Plan_LR_Workbook_2027_Workers_Comp.xlsx | C21: 2026-08-02 00:03 | D21: 3.4.0 | E21: 63 | F21: PASS WITH 1 WARNING(S) | V21: NC
A22: Umbrella | B22: Plan_LR_Workbook_2027_Umbrella.xlsx | C22: 2026-08-02 00:03 | D22: 3.4.0 | E22: 63 | F22: PASS WITH 1 WARNING(S) | V22: OH
A23: Inland Marine | B23: Plan_LR_Workbook_2027_Inland_Marine.xlsx | C23: 2026-08-02 00:03 | D23: 3.4.0 | E23: 63 | F23: PASS WITH 1 WARNING(S) | V23: PA
A24: TOTAL | E24: =SUM($E$18:$E$23) -> 378 | V24: SC
V25: TN
A26: Every figure in this book is a harvested value from these files — it cannot drift from them, and it cannot follow them either. Rebuild after any change. | V26: VA
V27: WV
V28: WI

Sheet State Summary
A1: State Summary — every line, one row per state (2027 plan)
A2: Adjusted-EP weighted across the lines and business units in view (set them on Control). Harvested values; the aggregation is live. Rate-change history shows only where the filters resolve to a single combo — the same honesty rule as the per-LOB exhibit, one dimension deeper.
A3: Go to: | C3: =HYPERLINK("#Control!A1","Control") -> Control | E3: =HYPERLINK("#Portfolio!A1","Portfolio") -> Portfolio | G3: =HYPERLINK("#'Roll-ups'!A1","Roll-ups") -> Roll-ups | I3: =HYPERLINK("#'Program Flow'!A1","Program Flow") -> Program Flow | K3: =HYPERLINK("#Checks!A1","Checks") -> Checks
A5: ="Showing: "&IF(bkf_lob="All","every line",bkf_lob)&" | "&IF(bkf_bu="All","every business unit",bkf_bu)&IF(bkf_state="All",""," | (state filter does not apply here)") -> Showing: every line | every business unit
B6: Volume | C6: Schedule mods | F6: Rate change history — single-combo views only. T = taken, P = planned, * = not in the indication | T6: Engine levels | W6: CY 2027 plan — the bridge, left to right | AC6: CY 2028 indicative | AG6: Net selection — asserted vs the logged program
A7: State | B7: Adj plan EP | C7: Mod in indication | D7: Current mod | E7: Proj. mod, plan-yr end | F7: Chg 1 date | G7: Chg 1 | H7: T/P | I7: Chg 2 date | J7: Chg 2 | K7: T/P | L7: Chg 3 date | M7: Chg 3 | N7: T/P | O7: Chg 4 date | P7: Chg 4 | Q7: T/P | R7: # taken | S7: # planned | T7: Indication rate level | U7: 2027 earned rate level | V7: 2027 earned mod | W7: Projected LR (current level) | X7: x Rate earn-in (A_rate) | Y7: x Mod drift (A_mod) | Z7: x Other adj (A_other) | AA7: ="= CY 2027 plan LR" -> = CY 2027 plan LR | AB7: Mix (pts) | AC7: Net trend | AD7: Rate earn-in +1 | AE7: Mod drift +1 | AF7: CY 2028 plan LR | AG7: Net rate sel | AH7: Plan LR — program basis | AI7: Program vs asserted (pts)
A8: AZ | B8: =SUMIFS(_book!$F$2:$F$379,_book!$C$2:$C$379,$A8,_book!$A$2:$A$379,bkc_lob,_book!$B$2:$B$379,bkc_bu) -> 459000 | C8: =IF(SUMIFS(_book!$F$2:$F$379,_book!$C$2:$C$379,$A8,_book!$A$2:$A$379,bkc_lob,_book!$B$2:$B$379,bkc_bu)=0,"—",SUMIFS(_book!$AV$2:$AV$379,_book!$C$2:$C$379,$A8,_book!$A$2:$A$379,bkc_lob,_book!$B$2:$B$379,bkc_bu)/SUMIFS(_book!$F$2:$F$379,_book!$C$2:$C$379,$A8,_book!$A$2:$A$379,bkc_lob,_book!$B$2:$B$379,bkc_bu)) -> 0.90530283 | D8: =IF(SUMIFS(_book!$F$2:$F$379,_book!$C$2:$C$379,$A8,_book!$A$2:$A$379,bkc_lob,_book!$B$2:$B$379,bkc_bu)=0,"—",SUMIFS(_book!$AW$2:$AW$379,_book!$C$2:$C$379,$A8,_book!$A$2:$A$379,bkc_lob,_book!$B$2:$B$379,bkc_bu)/SUMIFS(_book!$F$2:$F$379,_book!$C$2:$C$379,$A8,_book!$A$2:$A$379,bkc_lob,_book!$B$2:$B$379,bkc_bu)) -> 0.90122876 | E8: =IF(SUMIFS(_book!$F$2:$F$379,_book!$C$2:$C$379,$A8,_book!$A$2:$A$379,bkc_lob,_book!$B$2:$B$379,bkc_bu)=0,"—",SUMIFS(_book!$AX$2:$AX$379,_book!$C$2:$C$379,$A8,_book!$A$2:$A$379,bkc_lob,_book!$B$2:$B$379,bkc_bu)/SUMIFS(_book!$F$2:$F$379,_book!$C$2:$C$379,$A8,_book!$A$2:$A$379,bkc_lob,_book!$B$2:$B$379,bkc_bu)) -> 0.90308061 | F8: =IF(COUNTIFS(_book!$D$2:$D$379,"?*",_book!$C$2:$C$379,$A8,_book!$A$2:$A$379,bkc_lob,_book!$B$2:$B$379,bkc_bu)<>1,"—",INDEX(_book!$DG$2:$DG$379,MATCH(bkf_lob&"|"&bkf_bu&"|"&$A8,_book!$E$2:$E$379,0))) -> — | G8: =IF(COUNTIFS(_book!$D$2:$D$379,"?*",_book!$C$2:$C$379,$A8,_book!$A$2:$A$379,bkc_lob,_book!$B$2:$B$379,bkc_bu)<>1,"—",INDEX(_book!$DH$2:$DH$379,MATCH(bkf_lob&"|"&bkf_bu&"|"&$A8,_book!$E$2:$E$379,0))) -> — | H8: =IF(COUNTIFS(_book!$D$2:$D$379,"?*",_book!$C$2:$C$379,$A8,_book!$A$2:$A$379,bkc_lob,_book!$B$2:$B$379,bkc_bu)<>1,"—",INDEX(_book!$DI$2:$DI$379,MATCH(bkf_lob&"|"&bkf_bu&"|"&$A8,_book!$E$2:$E$379,0))) -> — | I8: =IF(COUNTIFS(_book!$D$2:$D$379,"?*",_book!$C$2:$C$379,$A8,_book!$A$2:$A$379,bkc_lob,_book!$B$2:$B$379,bkc_bu)<>1,"—",INDEX(_book!$DJ$2:$DJ$379,MATCH(bkf_lob&"|"&bkf_bu&"|"&$A8,_book!$E$2:$E$379,0))) -> — | J8: =IF(COUNTIFS(_book!$D$2:$D$379,"?*",_book!$C$2:$C$379,$A8,_book!$A$2:$A$379,bkc_lob,_book!$B$2:$B$379,bkc_bu)<>1,"—",INDEX(_book!$DK$2:$DK$379,MATCH(bkf_lob&"|"&bkf_bu&"|"&$A8,_book!$E$2:$E$379,0))) -> — | K8: =IF(COUNTIFS(_book!$D$2:$D$379,"?*",_book!$C$2:$C$379,$A8,_book!$A$2:$A$379,bkc_lob,_book!$B$2:$B$379,bkc_bu)<>1,"—",INDEX(_book!$DL$2:$DL$379,MATCH(bkf_lob&"|"&bkf_bu&"|"&$A8,_book!$E$2:$E$379,0))) -> — | L8: =IF(COUNTIFS(_book!$D$2:$D$379,"?*",_book!$C$2:$C$379,$A8,_book!$A$2:$A$379,bkc_lob,_book!$B$2:$B$379,bkc_bu)<>1,"—",INDEX(_book!$DM$2:$DM$379,MATCH(bkf_lob&"|"&bkf_bu&"|"&$A8,_book!$E$2:$E$379,0))) -> — | M8: =IF(COUNTIFS(_book!$D$2:$D$379,"?*",_book!$C$2:$C$379,$A8,_book!$A$2:$A$379,bkc_lob,_book!$B$2:$B$379,bkc_bu)<>1,"—",INDEX(_book!$DN$2:$DN$379,MATCH(bkf_lob&"|"&bkf_bu&"|"&$A8,_book!$E$2:$E$379,0))) -> — | N8: =IF(COUNTIFS(_book!$D$2:$D$379,"?*",_book!$C$2:$C$379,$A8,_book!$A$2:$A$379,bkc_lob,_book!$B$2:$B$379,bkc_bu)<>1,"—",INDEX(_book!$DO$2:$DO$379,MATCH(bkf_lob&"|"&bkf_bu&"|"&$A8,_book!$E$2:$E$379,0))) -> — | O8: =IF(COUNTIFS(_book!$D$2:$D$379,"?*",_book!$C$2:$C$379,$A8,_book!$A$2:$A$379,bkc_lob,_book!$B$2:$B$379,bkc_bu)<>1,"—",INDEX(_book!$DP$2:$DP$379,MATCH(bkf_lob&"|"&bkf_bu&"|"&$A8,_book!$E$2:$E$379,0))) -> — | P8: =IF(COUNTIFS(_book!$D$2:$D$379,"?*",_book!$C$2:$C$379,$A8,_book!$A$2:$A$379,bkc_lob,_book!$B$2:$B$379,bkc_bu)<>1,"—",INDEX(_book!$DQ$2:$DQ$379,MATCH(bkf_lob&"|"&bkf_bu&"|"&$A8,_book!$E$2:$E$379,0))) -> — | Q8: =IF(COUNTIFS(_book!$D$2:$D$379,"?*",_book!$C$2:$C$379,$A8,_book!$A$2:$A$379,bkc_lob,_book!$B$2:$B$379,bkc_bu)<>1,"—",INDEX(_book!$DR$2:$DR$379,MATCH(bkf_lob&"|"&bkf_bu&"|"&$A8,_book!$E$2:$E$379,0))) -> — | R8: =SUMIFS(_book!$AC$2:$AC$379,_book!$C$2:$C$379,$A8,_book!$A$2:$A$379,bkc_lob,_book!$B$2:$B$379,bkc_bu) -> 24 | S8: =SUMIFS(_book!$AD$2:$AD$379,_book!$C$2:$C$379,$A8,_book!$A$2:$A$379,bkc_lob,_book!$B$2:$B$379,bkc_bu) -> 12 | T8: =IF(SUMIFS(_book!$F$2:$F$379,_book!$C$2:$C$379,$A8,_book!$A$2:$A$379,bkc_lob,_book!$B$2:$B$379,bkc_bu)=0,"—",SUMIFS(_book!$AH$2:$AH$379,_book!$C$2:$C$379,$A8,_book!$A$2:$A$379,bkc_lob,_book!$B$2:$B$379,bkc_bu)/SUMIFS(_book!$F$2:$F$379,_book!$C$2:$C$379,$A8,_book!$A$2:$A$379,bkc_lob,_book!$B$2:$B$379,bkc_bu)) -> 1.0551556 | U8: =IF(SUMIFS(_book!$F$2:$F$379,_book!$C$2:$C$379,$A8,_book!$A$2:$A$379,bkc_lob,_book!$B$2:$B$379,bkc_bu)=0,"—",SUMIFS(_book!$AI$2:$AI$379,_book!$C$2:$C$379,$A8,_book!$A$2:$A$379,bkc_lob,_book!$B$2:$B$379,bkc_bu)/SUMIFS(_book!$F$2:$F$379,_book!$C$2:$C$379,$A8,_book!$A$2:$A$379,bkc_lob,_book!$B$2:$B$379,bkc_bu)) -> 1.0591696 | V8: =IF(SUMIFS(_book!$F$2:$F$379,_book!$C$2:$C$379,$A8,_book!$A$2:$A$379,bkc_lob,_book!$B$2:$B$379,bkc_bu)=0,"—",SUMIFS(_book!$AJ$2:$AJ$379,_book!$C$2:$C$379,$A8,_book!$A$2:$A$379,bkc_lob,_book!$B$2:$B$379,bkc_bu)/SUMIFS(_book!$F$2:$F$379,_book!$C$2:$C$379,$A8,_book!$A$2:$A$379,bkc_lob,_book!$B$2:$B$379,bkc_bu)) -> 0.90161575 | W8: =IF(SUMIFS(_book!$F$2:$F$379,_book!$C$2:$C$379,$A8,_book!$A$2:$A$379,bkc_lob,_book!$B$2:$B$379,bkc_bu)=0,"—",SUMIFS(_book!$AN$2:$AN$379,_book!$C$2:$C$379,$A8,_book!$A$2:$A$379,bkc_lob,_book!$B$2:$B$379,bkc_bu)/SUMIFS(_book!$F$2:$F$379,_book!$C$2:$C$379,$A8,_book!$A$2:$A$379,bkc_lob,_book!$B$2:$B$379,bkc_bu)) -> 0.64023747 | X8: =IF(SUMIFS(_book!$F$2:$F$379,_book!$C$2:$C$379,$A8,_book!$A$2:$A$379,bkc_lob,_book!$B$2:$B$379,bkc_bu)=0,"—",SUMIFS(_book!$AK$2:$AK$379,_book!$C$2:$C$379,$A8,_book!$A$2:$A$379,bkc_lob,_book!$B$2:$B$379,bkc_bu)/SUMIFS(_book!$F$2:$F$379,_book!$C$2:$C$379,$A8,_book!$A$2:$A$379,bkc_lob,_book!$B$2:$B$379,bkc_bu)) -> 0.99631275 | Y8: =IF(SUMIFS(_book!$F$2:$F$379,_book!$C$2:$C$379,$A8,_book!$A$2:$A$379,bkc_lob,_book!$B$2:$B$379,bkc_bu)=0,"—",SUMIFS(_book!$AL$2:$AL$379,_book!$C$2:$C$379,$A8,_book!$A$2:$A$379,bkc_lob,_book!$B$2:$B$379,bkc_bu)/SUMIFS(_book!$F$2:$F$379,_book!$C$2:$C$379,$A8,_book!$A$2:$A$379,bkc_lob,_book!$B$2:$B$379,bkc_bu)) -> 1.0037577 | Z8: =IF(SUMIFS(_book!$F$2:$F$379,_book!$C$2:$C$379,$A8,_book!$A$2:$A$379,bkc_lob,_book!$B$2:$B$379,bkc_bu)=0,"—",SUMIFS(_book!$AM$2:$AM$379,_book!$C$2:$C$379,$A8,_book!$A$2:$A$379,bkc_lob,_book!$B$2:$B$379,bkc_bu)/SUMIFS(_book!$F$2:$F$379,_book!$C$2:$C$379,$A8,_book!$A$2:$A$379,bkc_lob,_book!$B$2:$B$379,bkc_bu)) -> 1 | AA8: =IF(COUNTIFS(_book!$D$2:$D$379,"?*",_book!$C$2:$C$379,$A8,_book!$A$2:$A$379,bkc_lob,_book!$B$2:$B$379,bkc_bu)=0,"",IF(COUNTIFS(_book!$D$2:$D$379,"?*",_book!$C$2:$C$379,$A8,_book!$A$2:$A$379,bkc_lob,_book!$B$2:$B$379,bkc_bu)=1,$W8*$X8*$Y8*$Z8,IF(SUMIFS(_book!$F$2:$F$379,_book!$C$2:$C$379,$A8,_book!$A$2:$A$379,bkc_lob,_book!$B$2:$B$379,bkc_bu)=0,"—",SUMIFS(_book!$AO$2:$AO$379,_book!$C$2:$C$379,$A8,_book!$A$2:$A$379,bkc_lob,_book!$B$2:$B$379,bkc_bu)/SUMIFS(_book!$F$2:$F$379,_book!$C$2:$C$379,$A8,_book!$A$2:$A$379,bkc_lob,_book!$B$2:$B$379,bkc_bu)))) -> 0.64024221 | AB8: =IF(COUNTIFS(_book!$D$2:$D$379,"?*",_book!$C$2:$C$379,$A8,_book!$A$2:$A$379,bkc_lob,_book!$B$2:$B$379,bkc_bu)<=1,"",($AA8-$W8*$X8*$Y8*$Z8)*100) -> -0.0031464289 | AC8: =IF(SUMIFS(_book!$F$2:$F$379,_book!$C$2:$C$379,$A8,_book!$A$2:$A$379,bkc_lob,_book!$B$2:$B$379,bkc_bu)=0,"—",SUMIFS(_book!$AQ$2:$AQ$379,_book!$C$2:$C$379,$A8,_book!$A$2:$A$379,bkc_lob,_book!$B$2:$B$379,bkc_bu)/SUMIFS(_book!$F$2:$F$379,_book!$C$2:$C$379,$A8,_book!$A$2:$A$379,bkc_lob,_book!$B$2:$B$379,bkc_bu)) -> 0 | AD8: =IF(SUMIFS(_book!$F$2:$F$379,_book!$C$2:$C$379,$A8,_book!$A$2:$A$379,bkc_lob,_book!$B$2:$B$379,bkc_bu)=0,"—",SUMIFS(_book!$AR$2:$AR$379,_book!$C$2:$C$379,$A8,_book!$A$2:$A$379,bkc_lob,_book!$B$2:$B$379,bkc_bu)/SUMIFS(_book!$F$2:$F$379,_book!$C$2:$C$379,$A8,_book!$A$2:$A$379,bkc_lob,_book!$B$2:$B$379,bkc_bu)) -> 0.97351169 | AE8: =IF(SUMIFS(_book!$F$2:$F$379,_book!$C$2:$C$379,$A8,_book!$A$2:$A$379,bkc_lob,_book!$B$2:$B$379,bkc_bu)=0,"—",SUMIFS(_book!$AS$2:$AS$379,_book!$C$2:$C$379,$A8,_book!$A$2:$A$379,bkc_lob,_book!$B$2:$B$379,bkc_bu)/SUMIFS(_book!$F$2:$F$379,_book!$C$2:$C$379,$A8,_book!$A$2:$A$379,bkc_lob,_book!$B$2:$B$379,bkc_bu)) -> 1.0024519 | AF8: =IF(COUNTIFS(_book!$D$2:$D$379,"?*",_book!$C$2:$C$379,$A8,_book!$A$2:$A$379,bkc_lob,_book!$B$2:$B$379,bkc_bu)=0,"",IF(COUNTIFS(_book!$D$2:$D$379,"?*",_book!$C$2:$C$379,$A8,_book!$A$2:$A$379,bkc_lob,_book!$B$2:$B$379,bkc_bu)=1,$W8*(1+$AC8)*$AD8*$AE8*$Z8,IF(SUMIFS(_book!$F$2:$F$379,_book!$C$2:$C$379,$A8,_book!$A$2:$A$379,bkc_lob,_book!$B$2:$B$379,bkc_bu)=0,"—",SUMIFS(_book!$AP$2:$AP$379,_book!$C$2:$C$379,$A8,_book!$A$2:$A$379,bkc_lob,_book!$B$2:$B$379,bkc_bu)/SUMIFS(_book!$F$2:$F$379,_book!$C$2:$C$379,$A8,_book!$A$2:$A$379,bkc_lob,_book!$B$2:$B$379,bkc_bu)))) -> 0.62489153 | AG8: =IF(COUNTIFS(_book!$D$2:$D$379,"?*",_book!$C$2:$C$379,$A8,_book!$A$2:$A$379,bkc_lob,_book!$B$2:$B$379,bkc_bu)=0,"",IF(SUMIFS(_book!$V$2:$V$379,_book!$C$2:$C$379,$A8,_book!$A$2:$A$379,bkc_lob,_book!$B$2:$B$379,bkc_bu)=0,"—",SUMIFS(_book!$W$2:$W$379,_book!$C$2:$C$379,$A8,_book!$A$2:$A$379,bkc_lob,_book!$B$2:$B$379,bkc_bu)/SUMIFS(_book!$V$2:$V$379,_book!$C$2:$C$379,$A8,_book!$A$2:$A$379,bkc_lob,_book!$B$2:$B$379,bkc_bu))) -> — | AH8: =IF(SUMIFS(_book!$V$2:$V$379,_book!$C$2:$C$379,$A8,_book!$A$2:$A$379,bkc_lob,_book!$B$2:$B$379,bkc_bu)=0,"—",IF(SUMIFS(_book!$F$2:$F$379,_book!$C$2:$C$379,$A8,_book!$A$2:$A$379,bkc_lob,_book!$B$2:$B$379,bkc_bu)=0,"—",SUMIFS(_book!$AT$2:$AT$379,_book!$C$2:$C$379,$A8,_book!$A$2:$A$379,bkc_lob,_book!$B$2:$B$379,bkc_bu)/SUMIFS(_book!$F$2:$F$379,_book!$C$2:$C$379,$A8,_book!$A$2:$A$379,bkc_lob,_book!$B$2:$B$379,bkc_bu))) -> — | AI8: =IF(SUMIFS(_book!$V$2:$V$379,_book!$C$2:$C$379,$A8,_book!$A$2:$A$379,bkc_lob,_book!$B$2:$B$379,bkc_bu)=0,"—",($AH8-$AA8)*100) -> —
A9: CO | B9: =SUMIFS(_book!$F$2:$F$379,_book!$C$2:$C$379,$A9,_book!$A$2:$A$379,bkc_lob,_book!$B$2:$B$379,bkc_bu) -> 1122000 | C9: =IF(SUMIFS(_book!$F$2:$F$379,_book!$C$2:$C$379,$A9,_book!$A$2:$A$379,bkc_lob,_book!$B$2:$B$379,bkc_bu)=0,"—",SUMIFS(_book!$AV$2:$AV$379,_book!$C$2:$C$379,$A9,_book!$A$2:$A$379,bkc_lob,_book!$B$2:$B$379,bkc_bu)/SUMIFS(_book!$F$2:$F$379,_book!$C$2:$C$379,$A9,_book!$A$2:$A$379,bkc_lob,_book!$B$2:$B$379,bkc_bu)) -> 0.92858824 | D9: =IF(SUMIFS(_book!$F$2:$F$379,_book!$C$2:$C$379,$A9,_book!$A$2:$A$379,bkc_lob,_book!$B$2:$B$379,bkc_bu)=0,"—",SUMIFS(_book!$AW$2:$AW$379,_book!$C$2:$C$379,$A9,_book!$A$2:$A$379,bkc_lob,_book!$B$2:$B$379,bkc_bu)/SUMIFS(_book!$F$2:$F$379,_book!$C$2:$C$379,$A9,_book!$A$2:$A$379,bkc_lob,_book!$B$2:$B$379,bkc_bu)) -> 0.91858824 | E9: =IF(SUMIFS(_book!$F$2:$F$379,_book!$C$2:$C$379,$A9,_book!$A$2:$A$379,bkc_lob,_book!$B$2:$B$379,bkc_bu)=0,"—",SUMIFS(_book!$AX$2:$AX$379,_book!$C$2:$C$379,$A9,_book!$A$2:$A$379,bkc_lob,_book!$B$2:$B$379,bkc_bu)/SUMIFS(_book!$F$2:$F$379,_book!$C$2:$C$379,$A9,_book!$A$2:$A$379,bkc_lob,_book!$B$2:$B$379,bkc_bu)) -> 0.92358824 | F9: =IF(COUNTIFS(_book!$D$2:$D$379,"?*",_book!$C$2:$C$379,$A9,_book!$A$2:$A$379,bkc_lob,_book!$B$2:$B$379,bkc_bu)<>1,"—",INDEX(_book!$DG$2:$DG$379,MATCH(bkf_lob&"|"&bkf_bu&"|"&$A9,_book!$E$2:$E$379,0))) -> — | G9: =IF(COUNTIFS(_book!$D$2:$D$379,"?*",_book!$C$2:$C$379,$A9,_book!$A$2:$A$379,bkc_lob,_book!$B$2:$B$379,bkc_bu)<>1,"—",INDEX(_book!$DH$2:$DH$379,MATCH(bkf_lob&"|"&bkf_bu&"|"&$A9,_book!$E$2:$E$379,0))) -> — | H9: =IF(COUNTIFS(_book!$D$2:$D$379,"?*",_book!$C$2:$C$379,$A9,_book!$A$2:$A$379,bkc_lob,_book!$B$2:$B$379,bkc_bu)<>1,"—",INDEX(_book!$DI$2:$DI$379,MATCH(bkf_lob&"|"&bkf_bu&"|"&$A9,_book!$E$2:$E$379,0))) -> — | I9: =IF(COUNTIFS(_book!$D$2:$D$379,"?*",_book!$C$2:$C$379,$A9,_book!$A$2:$A$379,bkc_lob,_book!$B$2:$B$379,bkc_bu)<>1,"—",INDEX(_book!$DJ$2:$DJ$379,MATCH(bkf_lob&"|"&bkf_bu&"|"&$A9,_book!$E$2:$E$379,0))) -> — | J9: =IF(COUNTIFS(_book!$D$2:$D$379,"?*",_book!$C$2:$C$379,$A9,_book!$A$2:$A$379,bkc_lob,_book!$B$2:$B$379,bkc_bu)<>1,"—",INDEX(_book!$DK$2:$DK$379,MATCH(bkf_lob&"|"&bkf_bu&"|"&$A9,_book!$E$2:$E$379,0))) -> — | K9: =IF(COUNTIFS(_book!$D$2:$D$379,"?*",_book!$C$2:$C$379,$A9,_book!$A$2:$A$379,bkc_lob,_book!$B$2:$B$379,bkc_bu)<>1,"—",INDEX(_book!$DL$2:$DL$379,MATCH(bkf_lob&"|"&bkf_bu&"|"&$A9,_book!$E$2:$E$379,0))) -> — | L9: =IF(COUNTIFS(_book!$D$2:$D$379,"?*",_book!$C$2:$C$379,$A9,_book!$A$2:$A$379,bkc_lob,_book!$B$2:$B$379,bkc_bu)<>1,"—",INDEX(_book!$DM$2:$DM$379,MATCH(bkf_lob&"|"&bkf_bu&"|"&$A9,_book!$E$2:$E$379,0))) -> — | M9: =IF(COUNTIFS(_book!$D$2:$D$379,"?*",_book!$C$2:$C$379,$A9,_book!$A$2:$A$379,bkc_lob,_book!$B$2:$B$379,bkc_bu)<>1,"—",INDEX(_book!$DN$2:$DN$379,MATCH(bkf_lob&"|"&bkf_bu&"|"&$A9,_book!$E$2:$E$379,0))) -> — | N9: =IF(COUNTIFS(_book!$D$2:$D$379,"?*",_book!$C$2:$C$379,$A9,_book!$A$2:$A$379,bkc_lob,_book!$B$2:$B$379,bkc_bu)<>1,"—",INDEX(_book!$DO$2:$DO$379,MATCH(bkf_lob&"|"&bkf_bu&"|"&$A9,_book!$E$2:$E$379,0))) -> — | O9: =IF(COUNTIFS(_book!$D$2:$D$379,"?*",_book!$C$2:$C$379,$A9,_book!$A$2:$A$379,bkc_lob,_book!$B$2:$B$379,bkc_bu)<>1,"—",INDEX(_book!$DP$2:$DP$379,MATCH(bkf_lob&"|"&bkf_bu&"|"&$A9,_book!$E$2:$E$379,0))) -> — | P9: =IF(COUNTIFS(_book!$D$2:$D$379,"?*",_book!$C$2:$C$379,$A9,_book!$A$2:$A$379,bkc_lob,_book!$B$2:$B$379,bkc_bu)<>1,"—",INDEX(_book!$DQ$2:$DQ$379,MATCH(bkf_lob&"|"&bkf_bu&"|"&$A9,_book!$E$2:$E$379,0))) -> — | Q9: =IF(COUNTIFS(_book!$D$2:$D$379,"?*",_book!$C$2:$C$379,$A9,_book!$A$2:$A$379,bkc_lob,_book!$B$2:$B$379,bkc_bu)<>1,"—",INDEX(_book!$DR$2:$DR$379,MATCH(bkf_lob&"|"&bkf_bu&"|"&$A9,_book!$E$2:$E$379,0))) -> — | R9: =SUMIFS(_book!$AC$2:$AC$379,_book!$C$2:$C$379,$A9,_book!$A$2:$A$379,bkc_lob,_book!$B$2:$B$379,bkc_bu) -> 18 | S9: =SUMIFS(_book!$AD$2:$AD$379,_book!$C$2:$C$379,$A9,_book!$A$2:$A$379,bkc_lob,_book!$B$2:$B$379,bkc_bu) -> 6 | T9: =IF(SUMIFS(_book!$F$2:$F$379,_book!$C$2:$C$379,$A9,_book!$A$2:$A$379,bkc_lob,_book!$B$2:$B$379,bkc_bu)=0,"—",SUMIFS(_book!$AH$2:$AH$379,_book!$C$2:$C$379,$A9,_book!$A$2:$A$379,bkc_lob,_book!$B$2:$B$379,bkc_bu)/SUMIFS(_book!$F$2:$F$379,_book!$C$2:$C$379,$A9,_book!$A$2:$A$379,bkc_lob,_book!$B$2:$B$379,bkc_bu)) -> 1.040303 | U9: =IF(SUMIFS(_book!$F$2:$F$379,_book!$C$2:$C$379,$A9,_book!$A$2:$A$379,bkc_lob,_book!$B$2:$B$379,bkc_bu)=0,"—",SUMIFS(_book!$AI$2:$AI$379,_book!$C$2:$C$379,$A9,_book!$A$2:$A$379,bkc_lob,_book!$B$2:$B$379,bkc_bu)/SUMIFS(_book!$F$2:$F$379,_book!$C$2:$C$379,$A9,_book!$A$2:$A$379,bkc_lob,_book!$B$2:$B$379,bkc_bu)) -> 1.038619 | V9: =IF(SUMIFS(_book!$F$2:$F$379,_book!$C$2:$C$379,$A9,_book!$A$2:$A$379,bkc_lob,_book!$B$2:$B$379,bkc_bu)=0,"—",SUMIFS(_book!$AJ$2:$AJ$379,_book!$C$2:$C$379,$A9,_book!$A$2:$A$379,bkc_lob,_book!$B$2:$B$379,bkc_bu)/SUMIFS(_book!$F$2:$F$379,_book!$C$2:$C$379,$A9,_book!$A$2:$A$379,bkc_lob,_book!$B$2:$B$379,bkc_bu)) -> 0.91963312 | W9: =IF(SUMIFS(_book!$F$2:$F$379,_book!$C$2:$C$379,$A9,_book!$A$2:$A$379,bkc_lob,_book!$B$2:$B$379,bkc_bu)=0,"—",SUMIFS(_book!$AN$2:$AN$379,_book!$C$2:$C$379,$A9,_book!$A$2:$A$379,bkc_lob,_book!$B$2:$B$379,bkc_bu)/SUMIFS(_book!$F$2:$F$379,_book!$C$2:$C$379,$A9,_book!$A$2:$A$379,bkc_lob,_book!$B$2:$B$379,bkc_bu)) -> 0.64250289 | X9: =IF(SUMIFS(_book!$F$2:$F$379,_book!$C$2:$C$379,$A9,_book!$A$2:$A$379,bkc_lob,_book!$B$2:$B$379,bkc_bu)=0,"—",SUMIFS(_book!$AK$2:$AK$379,_book!$C$2:$C$379,$A9,_book!$A$2:$A$379,bkc_lob,_book!$B$2:$B$379,bkc_bu)/SUMIFS(_book!$F$2:$F$379,_book!$C$2:$C$379,$A9,_book!$A$2:$A$379,bkc_lob,_book!$B$2:$B$379,bkc_bu)) -> 1.0017141 | Y9: =IF(SUMIFS(_book!$F$2:$F$379,_book!$C$2:$C$379,$A9,_book!$A$2:$A$379,bkc_lob,_book!$B$2:$B$379,bkc_bu)=0,"—",SUMIFS(_book!$AL$2:$AL$379,_book!$C$2:$C$379,$A9,_book!$A$2:$A$379,bkc_lob,_book!$B$2:$B$379,bkc_bu)/SUMIFS(_book!$F$2:$F$379,_book!$C$2:$C$379,$A9,_book!$A$2:$A$379,bkc_lob,_book!$B$2:$B$379,bkc_bu)) -> 1.0097775 | Z9: =IF(SUMIFS(_book!$F$2:$F$379,_book!$C$2:$C$379,$A9,_book!$A$2:$A$379,bkc_lob,_book!$B$2:$B$379,bkc_bu)=0,"—",SUMIFS(_book!$AM$2:$AM$379,_book!$C$2:$C$379,$A9,_book!$A$2:$A$379,bkc_lob,_book!$B$2:$B$379,bkc_bu)/SUMIFS(_book!$F$2:$F$379,_book!$C$2:$C$379,$A9,_book!$A$2:$A$379,bkc_lob,_book!$B$2:$B$379,bkc_bu)) -> 1 | AA9: =IF(COUNTIFS(_book!$D$2:$D$379,"?*",_book!$C$2:$C$379,$A9,_book!$A$2:$A$379,bkc_lob,_book!$B$2:$B$379,bkc_bu)=0,"",IF(COUNTIFS(_book!$D$2:$D$379,"?*",_book!$C$2:$C$379,$A9,_book!$A$2:$A$379,bkc_lob,_book!$B$2:$B$379,bkc_bu)=1,$W9*$X9*$Y9*$Z9,IF(SUMIFS(_book!$F$2:$F$379,_book!$C$2:$C$379,$A9,_book!$A$2:$A$379,bkc_lob,_book!$B$2:$B$379,bkc_bu)=0,"—",SUMIFS(_book!$AO$2:$AO$379,_book!$C$2:$C$379,$A9,_book!$A$2:$A$379,bkc_lob,_book!$B$2:$B$379,bkc_bu)/SUMIFS(_book!$F$2:$F$379,_book!$C$2:$C$379,$A9,_book!$A$2:$A$379,bkc_lob,_book!$B$2:$B$379,bkc_bu)))) -> 0.649976 | AB9: =IF(COUNTIFS(_book!$D$2:$D$379,"?*",_book!$C$2:$C$379,$A9,_book!$A$2:$A$379,bkc_lob,_book!$B$2:$B$379,bkc_bu)<=1,"",($AA9-$W9*$X9*$Y9*$Z9)*100) -> 0.0078916435 | AC9: =IF(SUMIFS(_book!$F$2:$F$379,_book!$C$2:$C$379,$A9,_book!$A$2:$A$379,bkc_lob,_book!$B$2:$B$379,bkc_bu)=0,"—",SUMIFS(_book!$AQ$2:$AQ$379,_book!$C$2:$C$379,$A9,_book!$A$2:$A$379,bkc_lob,_book!$B$2:$B$379,bkc_bu)/SUMIFS(_book!$F$2:$F$379,_book!$C$2:$C$379,$A9,_book!$A$2:$A$379,bkc_lob,_book!$B$2:$B$379,bkc_bu)) -> 0.0033333333 | AD9: =IF(SUMIFS(_book!$F$2:$F$379,_book!$C$2:$C$379,$A9,_book!$A$2:$A$379,bkc_lob,_book!$B$2:$B$379,bkc_bu)=0,"—",SUMIFS(_book!$AR$2:$AR$379,_book!$C$2:$C$379,$A9,_book!$A$2:$A$379,bkc_lob,_book!$B$2:$B$379,bkc_bu)/SUMIFS(_book!$F$2:$F$379,_book!$C$2:$C$379,$A9,_book!$A$2:$A$379,bkc_lob,_book!$B$2:$B$379,bkc_bu)) -> 0.98780118 | AE9: =IF(SUMIFS(_book!$F$2:$F$379,_book!$C$2:$C$379,$A9,_book!$A$2:$A$379,bkc_lob,_book!$B$2:$B$379,bkc_bu)=0,"—",SUMIFS(_book!$AS$2:$AS$379,_book!$C$2:$C$379,$A9,_book!$A$2:$A$379,bkc_lob,_book!$B$2:$B$379,bkc_bu)/SUMIFS(_book!$F$2:$F$379,_book!$C$2:$C$379,$A9,_book!$A$2:$A$379,bkc_lob,_book!$B$2:$B$379,bkc_bu)) -> 1.0061447 | AF9: =IF(COUNTIFS(_book!$D$2:$D$379,"?*",_book!$C$2:$C$379,$A9,_book!$A$2:$A$379,bkc_lob,_book!$B$2:$B$379,bkc_bu)=0,"",IF(COUNTIFS(_book!$D$2:$D$379,"?*",_book!$C$2:$C$379,$A9,_book!$A$2:$A$379,bkc_lob,_book!$B$2:$B$379,bkc_bu)=1,$W9*(1+$AC9)*$AD9*$AE9*$Z9,IF(SUMIFS(_book!$F$2:$F$379,_book!$C$2:$C$379,$A9,_book!$A$2:$A$379,bkc_lob,_book!$B$2:$B$379,bkc_bu)=0,"—",SUMIFS(_book!$AP$2:$AP$379,_book!$C$2:$C$379,$A9,_book!$A$2:$A$379,bkc_lob,_book!$B$2:$B$379,bkc_bu)/SUMIFS(_book!$F$2:$F$379,_book!$C$2:$C$379,$A9,_book!$A$2:$A$379,bkc_lob,_book!$B$2:$B$379,bkc_bu)))) -> 0.64081577 | AG9: =IF(COUNTIFS(_book!$D$2:$D$379,"?*",_book!$C$2:$C$379,$A9,_book!$A$2:$A$379,bkc_lob,_book!$B$2:$B$379,bkc_bu)=0,"",IF(SUMIFS(_book!$V$2:$V$379,_book!$C$2:$C$379,$A9,_book!$A$2:$A$379,bkc_lob,_book!$B$2:$B$379,bkc_bu)=0,"—",SUMIFS(_book!$W$2:$W$379,_book!$C$2:$C$379,$A9,_book!$A$2:$A$379,bkc_lob,_book!$B$2:$B$379,bkc_bu)/SUMIFS(_book!$V$2:$V$379,_book!$C$2:$C$379,$A9,_book!$A$2:$A$379,bkc_lob,_book!$B$2:$B$379,bkc_bu))) -> — | AH9: =IF(SUMIFS(_book!$V$2:$V$379,_book!$C$2:$C$379,$A9,_book!$A$2:$A$379,bkc_lob,_book!$B$2:$B$379,bkc_bu)=0,"—",IF(SUMIFS(_book!$F$2:$F$379,_book!$C$2:$C$379,$A9,_book!$A$2:$A$379,bkc_lob,_book!$B$2:$B$379,bkc_bu)=0,"—",SUMIFS(_book!$AT$2:$AT$379,_book!$C$2:$C$379,$A9,_book!$A$2:$A$379,bkc_lob,_book!$B$2:$B$379,bkc_bu)/SUMIFS(_book!$F$2:$F$379,_book!$C$2:$C$379,$A9,_book!$A$2:$A$379,bkc_lob,_book!$B$2:$B$379,bkc_bu))) -> — | AI9: =IF(SUMIFS(_book!$V$2:$V$379,_book!$C$2:$C$379,$A9,_book!$A$2:$A$379,bkc_lob,_book!$B$2:$B$379,bkc_bu)=0,"—",($AH9-$AA9)*100) -> —
A10: DE | B10: =SUMIFS(_book!$F$2:$F$379,_book!$C$2:$C$379,$A10,_book!$A$2:$A$379,bkc_lob,_book!$B$2:$B$379,bkc_bu) -> 918000 | C10: =IF(SUMIFS(_book!$F$2:$F$379,_book!$C$2:$C$379,$A10,_book!$A$2:$A$379,bkc_lob,_book!$B$2:$B$379,bkc_bu)=0,"—",SUMIFS(_book!$AV$2:$AV$379,_book!$C$2:$C$379,$A10,_book!$A$2:$A$379,bkc_lob,_book!$B$2:$B$379,bkc_bu)/SUMIFS(_book!$F$2:$F$379,_book!$C$2:$C$379,$A10,_book!$A$2:$A$379,bkc_lob,_book!$B$2:$B$379,bkc_bu)) -> 0.92858824 | D10: =IF(SUMIFS(_book!$F$2:$F$379,_book!$C$2:$C$379,$A10,_book!$A$2:$A$379,bkc_lob,_book!$B$2:$B$379,bkc_bu)=0,"—",SUMIFS(_book!$AW$2:$AW$379,_book!$C$2:$C$379,$A10,_book!$A$2:$A$379,bkc_lob,_book!$B$2:$B$379,bkc_bu)/SUMIFS(_book!$F$2:$F$379,_book!$C$2:$C$379,$A10,_book!$A$2:$A$379,bkc_lob,_book!$B$2:$B$379,bkc_bu)) -> 0.91858824 | E10: =IF(SUMIFS(_book!$F$2:$F$379,_book!$C$2:$C$379,$A10,_book!$A$2:$A$379,bkc_lob,_book!$B$2:$B$379,bkc_bu)=0,"—",SUMIFS(_book!$AX$2:$AX$379,_book!$C$2:$C$379,$A10,_book!$A$2:$A$379,bkc_lob,_book!$B$2:$B$379,bkc_bu)/SUMIFS(_book!$F$2:$F$379,_book!$C$2:$C$379,$A10,_book!$A$2:$A$379,bkc_lob,_book!$B$2:$B$379,bkc_bu)) -> 0.93858824 | F10: =IF(COUNTIFS(_book!$D$2:$D$379,"?*",_book!$C$2:$C$379,$A10,_book!$A$2:$A$379,bkc_lob,_book!$B$2:$B$379,bkc_bu)<>1,"—",INDEX(_book!$DG$2:$DG$379,MATCH(bkf_lob&"|"&bkf_bu&"|"&$A10,_book!$E$2:$E$379,0))) -> — | G10: =IF(COUNTIFS(_book!$D$2:$D$379,"?*",_book!$C$2:$C$379,$A10,_book!$A$2:$A$379,bkc_lob,_book!$B$2:$B$379,bkc_bu)<>1,"—",INDEX(_book!$DH$2:$DH$379,MATCH(bkf_lob&"|"&bkf_bu&"|"&$A10,_book!$E$2:$E$379,0))) -> — | H10: =IF(COUNTIFS(_book!$D$2:$D$379,"?*",_book!$C$2:$C$379,$A10,_book!$A$2:$A$379,bkc_lob,_book!$B$2:$B$379,bkc_bu)<>1,"—",INDEX(_book!$DI$2:$DI$379,MATCH(bkf_lob&"|"&bkf_bu&"|"&$A10,_book!$E$2:$E$379,0))) -> — | I10: =IF(COUNTIFS(_book!$D$2:$D$379,"?*",_book!$C$2:$C$379,$A10,_book!$A$2:$A$379,bkc_lob,_book!$B$2:$B$379,bkc_bu)<>1,"—",INDEX(_book!$DJ$2:$DJ$379,MATCH(bkf_lob&"|"&bkf_bu&"|"&$A10,_book!$E$2:$E$379,0))) -> — | J10: =IF(COUNTIFS(_book!$D$2:$D$379,"?*",_book!$C$2:$C$379,$A10,_book!$A$2:$A$379,bkc_lob,_book!$B$2:$B$379,bkc_bu)<>1,"—",INDEX(_book!$DK$2:$DK$379,MATCH(bkf_lob&"|"&bkf_bu&"|"&$A10,_book!$E$2:$E$379,0))) -> — | K10: =IF(COUNTIFS(_book!$D$2:$D$379,"?*",_book!$C$2:$C$379,$A10,_book!$A$2:$A$379,bkc_lob,_book!$B$2:$B$379,bkc_bu)<>1,"—",INDEX(_book!$DL$2:$DL$379,MATCH(bkf_lob&"|"&bkf_bu&"|"&$A10,_book!$E$2:$E$379,0))) -> — | L10: =IF(COUNTIFS(_book!$D$2:$D$379,"?*",_book!$C$2:$C$379,$A10,_book!$A$2:$A$379,bkc_lob,_book!$B$2:$B$379,bkc_bu)<>1,"—",INDEX(_book!$DM$2:$DM$379,MATCH(bkf_lob&"|"&bkf_bu&"|"&$A10,_book!$E$2:$E$379,0))) -> — | M10: =IF(COUNTIFS(_book!$D$2:$D$379,"?*",_book!$C$2:$C$379,$A10,_book!$A$2:$A$379,bkc_lob,_book!$B$2:$B$379,bkc_bu)<>1,"—",INDEX(_book!$DN$2:$DN$379,MATCH(bkf_lob&"|"&bkf_bu&"|"&$A10,_book!$E$2:$E$379,0))) -> — | N10: =IF(COUNTIFS(_book!$D$2:$D$379,"?*",_book!$C$2:$C$379,$A10,_book!$A$2:$A$379,bkc_lob,_book!$B$2:$B$379,bkc_bu)<>1,"—",INDEX(_book!$DO$2:$DO$379,MATCH(bkf_lob&"|"&bkf_bu&"|"&$A10,_book!$E$2:$E$379,0))) -> — | O10: =IF(COUNTIFS(_book!$D$2:$D$379,"?*",_book!$C$2:$C$379,$A10,_book!$A$2:$A$379,bkc_lob,_book!$B$2:$B$379,bkc_bu)<>1,"—",INDEX(_book!$DP$2:$DP$379,MATCH(bkf_lob&"|"&bkf_bu&"|"&$A10,_book!$E$2:$E$379,0))) -> — | P10: =IF(COUNTIFS(_book!$D$2:$D$379,"?*",_book!$C$2:$C$379,$A10,_book!$A$2:$A$379,bkc_lob,_book!$B$2:$B$379,bkc_bu)<>1,"—",INDEX(_book!$DQ$2:$DQ$379,MATCH(bkf_lob&"|"&bkf_bu&"|"&$A10,_book!$E$2:$E$379,0))) -> — | Q10: =IF(COUNTIFS(_book!$D$2:$D$379,"?*",_book!$C$2:$C$379,$A10,_book!$A$2:$A$379,bkc_lob,_book!$B$2:$B$379,bkc_bu)<>1,"—",INDEX(_book!$DR$2:$DR$379,MATCH(bkf_lob&"|"&bkf_bu&"|"&$A10,_book!$E$2:$E$379,0))) -> — | R10: =SUMIFS(_book!$AC$2:$AC$379,_book!$C$2:$C$379,$A10,_book!$A$2:$A$379,bkc_lob,_book!$B$2:$B$379,bkc_bu) -> 6 | S10: =SUMIFS(_book!$AD$2:$AD$379,_book!$C$2:$C$379,$A10,_book!$A$2:$A$379,bkc_lob,_book!$B$2:$B$379,bkc_bu) -> 6 | T10: =IF(SUMIFS(_book!$F$2:$F$379,_book!$C$2:$C$379,$A10,_book!$A$2:$A$379,bkc_lob,_book!$B$2:$B$379,bkc_bu)=0,"—",SUMIFS(_book!$AH$2:$AH$379,_book!$C$2:$C$379,$A10,_book!$A$2:$A$379,bkc_lob,_book!$B$2:$B$379,bkc_bu)/SUMIFS(_book!$F$2:$F$379,_book!$C$2:$C$379,$A10,_book!$A$2:$A$379,bkc_lob,_book!$B$2:$B$379,bkc_bu)) -> 1.0166667 | U10: =IF(SUMIFS(_book!$F$2:$F$379,_book!$C$2:$C$379,$A10,_book!$A$2:$A$379,bkc_lob,_book!$B$2:$B$379,bkc_bu)=0,"—",SUMIFS(_book!$AI$2:$AI$379,_book!$C$2:$C$379,$A10,_book!$A$2:$A$379,bkc_lob,_book!$B$2:$B$379,bkc_bu)/SUMIFS(_book!$F$2:$F$379,_book!$C$2:$C$379,$A10,_book!$A$2:$A$379,bkc_lob,_book!$B$2:$B$379,bkc_bu)) -> 1.0183458 | V10: =IF(SUMIFS(_book!$F$2:$F$379,_book!$C$2:$C$379,$A10,_book!$A$2:$A$379,bkc_lob,_book!$B$2:$B$379,bkc_bu)=0,"—",SUMIFS(_book!$AJ$2:$AJ$379,_book!$C$2:$C$379,$A10,_book!$A$2:$A$379,bkc_lob,_book!$B$2:$B$379,bkc_bu)/SUMIFS(_book!$F$2:$F$379,_book!$C$2:$C$379,$A10,_book!$A$2:$A$379,bkc_lob,_book!$B$2:$B$379,bkc_bu)) -> 0.92497176 | W10: =IF(SUMIFS(_book!$F$2:$F$379,_book!$C$2:$C$379,$A10,_book!$A$2:$A$379,bkc_lob,_book!$B$2:$B$379,bkc_bu)=0,"—",SUMIFS(_book!$AN$2:$AN$379,_book!$C$2:$C$379,$A10,_book!$A$2:$A$379,bkc_lob,_book!$B$2:$B$379,bkc_bu)/SUMIFS(_book!$F$2:$F$379,_book!$C$2:$C$379,$A10,_book!$A$2:$A$379,bkc_lob,_book!$B$2:$B$379,bkc_bu)) -> 0.62481699 | X10: =IF(SUMIFS(_book!$F$2:$F$379,_book!$C$2:$C$379,$A10,_book!$A$2:$A$379,bkc_lob,_book!$B$2:$B$379,bkc_bu)=0,"—",SUMIFS(_book!$AK$2:$AK$379,_book!$C$2:$C$379,$A10,_book!$A$2:$A$379,bkc_lob,_book!$B$2:$B$379,bkc_bu)/SUMIFS(_book!$F$2:$F$379,_book!$C$2:$C$379,$A10,_book!$A$2:$A$379,bkc_lob,_book!$B$2:$B$379,bkc_bu)) -> 0.99840915 | Y10: =IF(SUMIFS(_book!$F$2:$F$379,_book!$C$2:$C$379,$A10,_book!$A$2:$A$379,bkc_lob,_book!$B$2:$B$379,bkc_bu)=0,"—",SUMIFS(_book!$AL$2:$AL$379,_book!$C$2:$C$379,$A10,_book!$A$2:$A$379,bkc_lob,_book!$B$2:$B$379,bkc_bu)/SUMIFS(_book!$F$2:$F$379,_book!$C$2:$C$379,$A10,_book!$A$2:$A$379,bkc_lob,_book!$B$2:$B$379,bkc_bu)) -> 1.0039481 | Z10: =IF(SUMIFS(_book!$F$2:$F$379,_book!$C$2:$C$379,$A10,_book!$A$2:$A$379,bkc_lob,_book!$B$2:$B$379,bkc_bu)=0,"—",SUMIFS(_book!$AM$2:$AM$379,_book!$C$2:$C$379,$A10,_book!$A$2:$A$379,bkc_lob,_book!$B$2:$B$379,bkc_bu)/SUMIFS(_book!$F$2:$F$379,_book!$C$2:$C$379,$A10,_book!$A$2:$A$379,bkc_lob,_book!$B$2:$B$379,bkc_bu)) -> 1.0066667 | AA10: =IF(COUNTIFS(_book!$D$2:$D$379,"?*",_book!$C$2:$C$379,$A10,_book!$A$2:$A$379,bkc_lob,_book!$B$2:$B$379,bkc_bu)=0,"",IF(COUNTIFS(_book!$D$2:$D$379,"?*",_book!$C$2:$C$379,$A10,_book!$A$2:$A$379,bkc_lob,_book!$B$2:$B$379,bkc_bu)=1,$W10*$X10*$Y10*$Z10,IF(SUMIFS(_book!$F$2:$F$379,_book!$C$2:$C$379,$A10,_book!$A$2:$A$379,bkc_lob,_book!$B$2:$B$379,bkc_bu)=0,"—",SUMIFS(_book!$AO$2:$AO$379,_book!$C$2:$C$379,$A10,_book!$A$2:$A$379,bkc_lob,_book!$B$2:$B$379,bkc_bu)/SUMIFS(_book!$F$2:$F$379,_book!$C$2:$C$379,$A10,_book!$A$2:$A$379,bkc_lob,_book!$B$2:$B$379,bkc_bu)))) -> 0.63049377 | AB10: =IF(COUNTIFS(_book!$D$2:$D$379,"?*",_book!$C$2:$C$379,$A10,_book!$A$2:$A$379,bkc_lob,_book!$B$2:$B$379,bkc_bu)<=1,"",($AA10-$W10*$X10*$Y10*$Z10)*100) -> 0.0032628341 | AC10: =IF(SUMIFS(_book!$F$2:$F$379,_book!$C$2:$C$379,$A10,_book!$A$2:$A$379,bkc_lob,_book!$B$2:$B$379,bkc_bu)=0,"—",SUMIFS(_book!$AQ$2:$AQ$379,_book!$C$2:$C$379,$A10,_book!$A$2:$A$379,bkc_lob,_book!$B$2:$B$379,bkc_bu)/SUMIFS(_book!$F$2:$F$379,_book!$C$2:$C$379,$A10,_book!$A$2:$A$379,bkc_lob,_book!$B$2:$B$379,bkc_bu)) -> 0 | AD10: =IF(SUMIFS(_book!$F$2:$F$379,_book!$C$2:$C$379,$A10,_book!$A$2:$A$379,bkc_lob,_book!$B$2:$B$379,bkc_bu)=0,"—",SUMIFS(_book!$AR$2:$AR$379,_book!$C$2:$C$379,$A10,_book!$A$2:$A$379,bkc_lob,_book!$B$2:$B$379,bkc_bu)/SUMIFS(_book!$F$2:$F$379,_book!$C$2:$C$379,$A10,_book!$A$2:$A$379,bkc_lob,_book!$B$2:$B$379,bkc_bu)) -> 0.99091832 | AE10: =IF(SUMIFS(_book!$F$2:$F$379,_book!$C$2:$C$379,$A10,_book!$A$2:$A$379,bkc_lob,_book!$B$2:$B$379,bkc_bu)=0,"—",SUMIFS(_book!$AS$2:$AS$379,_book!$C$2:$C$379,$A10,_book!$A$2:$A$379,bkc_lob,_book!$B$2:$B$379,bkc_bu)/SUMIFS(_book!$F$2:$F$379,_book!$C$2:$C$379,$A10,_book!$A$2:$A$379,bkc_lob,_book!$B$2:$B$379,bkc_bu)) -> 0.98557249 | AF10: =IF(COUNTIFS(_book!$D$2:$D$379,"?*",_book!$C$2:$C$379,$A10,_book!$A$2:$A$379,bkc_lob,_book!$B$2:$B$379,bkc_bu)=0,"",IF(COUNTIFS(_book!$D$2:$D$379,"?*",_book!$C$2:$C$379,$A10,_book!$A$2:$A$379,bkc_lob,_book!$B$2:$B$379,bkc_bu)=1,$W10*(1+$AC10)*$AD10*$AE10*$Z10,IF(SUMIFS(_book!$F$2:$F$379,_book!$C$2:$C$379,$A10,_book!$A$2:$A$379,bkc_lob,_book!$B$2:$B$379,bkc_bu)=0,"—",SUMIFS(_book!$AP$2:$AP$379,_book!$C$2:$C$379,$A10,_book!$A$2:$A$379,bkc_lob,_book!$B$2:$B$379,bkc_bu)/SUMIFS(_book!$F$2:$F$379,_book!$C$2:$C$379,$A10,_book!$A$2:$A$379,bkc_lob,_book!$B$2:$B$379,bkc_bu)))) -> 0.61409775 | AG10: =IF(COUNTIFS(_book!$D$2:$D$379,"?*",_book!$C$2:$C$379,$A10,_book!$A$2:$A$379,bkc_lob,_book!$B$2:$B$379,bkc_bu)=0,"",IF(SUMIFS(_book!$V$2:$V$379,_book!$C$2:$C$379,$A10,_book!$A$2:$A$379,bkc_lob,_book!$B$2:$B$379,bkc_bu)=0,"—",SUMIFS(_book!$W$2:$W$379,_book!$C$2:$C$379,$A10,_book!$A$2:$A$379,bkc_lob,_book!$B$2:$B$379,bkc_bu)/SUMIFS(_book!$V$2:$V$379,_book!$C$2:$C$379,$A10,_book!$A$2:$A$379,bkc_lob,_book!$B$2:$B$379,bkc_bu))) -> — | AH10: =IF(SUMIFS(_book!$V$2:$V$379,_book!$C$2:$C$379,$A10,_book!$A$2:$A$379,bkc_lob,_book!$B$2:$B$379,bkc_bu)=0,"—",IF(SUMIFS(_book!$F$2:$F$379,_book!$C$2:$C$379,$A10,_book!$A$2:$A$379,bkc_lob,_book!$B$2:$B$379,bkc_bu)=0,"—",SUMIFS(_book!$AT$2:$AT$379,_book!$C$2:$C$379,$A10,_book!$A$2:$A$379,bkc_lob,_book!$B$2:$B$379,bkc_bu)/SUMIFS(_book!$F$2:$F$379,_book!$C$2:$C$379,$A10,_book!$A$2:$A$379,bkc_lob,_book!$B$2:$B$379,bkc_bu))) -> — | AI10: =IF(SUMIFS(_book!$V$2:$V$379,_book!$C$2:$C$379,$A10,_book!$A$2:$A$379,bkc_lob,_book!$B$2:$B$379,bkc_bu)=0,"—",($AH10-$AA10)*100) -> —
A11: FL | B11: =SUMIFS(_book!$F$2:$F$379,_book!$C$2:$C$379,$A11,_book!$A$2:$A$379,bkc_lob,_book!$B$2:$B$379,bkc_bu) -> 714000 | C11: =IF(SUMIFS(_book!$F$2:$F$379,_book!$C$2:$C$379,$A11,_book!$A$2:$A$379,bkc_lob,_book!$B$2:$B$379,bkc_bu)=0,"—",SUMIFS(_book!$AV$2:$AV$379,_book!$C$2:$C$379,$A11,_book!$A$2:$A$379,bkc_lob,_book!$B$2:$B$379,bkc_bu)/SUMIFS(_book!$F$2:$F$379,_book!$C$2:$C$379,$A11,_book!$A$2:$A$379,bkc_lob,_book!$B$2:$B$379,bkc_bu)) -> 0.92858824 | D11: =IF(SUMIFS(_book!$F$2:$F$379,_book!$C$2:$C$379,$A11,_book!$A$2:$A$379,bkc_lob,_book!$B$2:$B$379,bkc_bu)=0,"—",SUMIFS(_book!$AW$2:$AW$379,_book!$C$2:$C$379,$A11,_book!$A$2:$A$379,bkc_lob,_book!$B$2:$B$379,bkc_bu)/SUMIFS(_book!$F$2:$F$379,_book!$C$2:$C$379,$A11,_book!$A$2:$A$379,bkc_lob,_book!$B$2:$B$379,bkc_bu)) -> 0.92168347 | E11: =IF(SUMIFS(_book!$F$2:$F$379,_book!$C$2:$C$379,$A11,_book!$A$2:$A$379,bkc_lob,_book!$B$2:$B$379,bkc_bu)=0,"—",SUMIFS(_book!$AX$2:$AX$379,_book!$C$2:$C$379,$A11,_book!$A$2:$A$379,bkc_lob,_book!$B$2:$B$379,bkc_bu)/SUMIFS(_book!$F$2:$F$379,_book!$C$2:$C$379,$A11,_book!$A$2:$A$379,bkc_lob,_book!$B$2:$B$379,bkc_bu)) -> 0.92168347 | F11: =IF(COUNTIFS(_book!$D$2:$D$379,"?*",_book!$C$2:$C$379,$A11,_book!$A$2:$A$379,bkc_lob,_book!$B$2:$B$379,bkc_bu)<>1,"—",INDEX(_book!$DG$2:$DG$379,MATCH(bkf_lob&"|"&bkf_bu&"|"&$A11,_book!$E$2:$E$379,0))) -> — | G11: =IF(COUNTIFS(_book!$D$2:$D$379,"?*",_book!$C$2:$C$379,$A11,_book!$A$2:$A$379,bkc_lob,_book!$B$2:$B$379,bkc_bu)<>1,"—",INDEX(_book!$DH$2:$DH$379,MATCH(bkf_lob&"|"&bkf_bu&"|"&$A11,_book!$E$2:$E$379,0))) -> — | H11: =IF(COUNTIFS(_book!$D$2:$D$379,"?*",_book!$C$2:$C$379,$A11,_book!$A$2:$A$379,bkc_lob,_book!$B$2:$B$379,bkc_bu)<>1,"—",INDEX(_book!$DI$2:$DI$379,MATCH(bkf_lob&"|"&bkf_bu&"|"&$A11,_book!$E$2:$E$379,0))) -> — | I11: =IF(COUNTIFS(_book!$D$2:$D$379,"?*",_book!$C$2:$C$379,$A11,_book!$A$2:$A$379,bkc_lob,_book!$B$2:$B$379,bkc_bu)<>1,"—",INDEX(_book!$DJ$2:$DJ$379,MATCH(bkf_lob&"|"&bkf_bu&"|"&$A11,_book!$E$2:$E$379,0))) -> — | J11: =IF(COUNTIFS(_book!$D$2:$D$379,"?*",_book!$C$2:$C$379,$A11,_book!$A$2:$A$379,bkc_lob,_book!$B$2:$B$379,bkc_bu)<>1,"—",INDEX(_book!$DK$2:$DK$379,MATCH(bkf_lob&"|"&bkf_bu&"|"&$A11,_book!$E$2:$E$379,0))) -> — | K11: =IF(COUNTIFS(_book!$D$2:$D$379,"?*",_book!$C$2:$C$379,$A11,_book!$A$2:$A$379,bkc_lob,_book!$B$2:$B$379,bkc_bu)<>1,"—",INDEX(_book!$DL$2:$DL$379,MATCH(bkf_lob&"|"&bkf_bu&"|"&$A11,_book!$E$2:$E$379,0))) -> — | L11: =IF(COUNTIFS(_book!$D$2:$D$379,"?*",_book!$C$2:$C$379,$A11,_book!$A$2:$A$379,bkc_lob,_book!$B$2:$B$379,bkc_bu)<>1,"—",INDEX(_book!$DM$2:$DM$379,MATCH(bkf_lob&"|"&bkf_bu&"|"&$A11,_book!$E$2:$E$379,0))) -> — | M11: =IF(COUNTIFS(_book!$D$2:$D$379,"?*",_book!$C$2:$C$379,$A11,_book!$A$2:$A$379,bkc_lob,_book!$B$2:$B$379,bkc_bu)<>1,"—",INDEX(_book!$DN$2:$DN$379,MATCH(bkf_lob&"|"&bkf_bu&"|"&$A11,_book!$E$2:$E$379,0))) -> — | N11: =IF(COUNTIFS(_book!$D$2:$D$379,"?*",_book!$C$2:$C$379,$A11,_book!$A$2:$A$379,bkc_lob,_book!$B$2:$B$379,bkc_bu)<>1,"—",INDEX(_book!$DO$2:$DO$379,MATCH(bkf_lob&"|"&bkf_bu&"|"&$A11,_book!$E$2:$E$379,0))) -> — | O11: =IF(COUNTIFS(_book!$D$2:$D$379,"?*",_book!$C$2:$C$379,$A11,_book!$A$2:$A$379,bkc_lob,_book!$B$2:$B$379,bkc_bu)<>1,"—",INDEX(_book!$DP$2:$DP$379,MATCH(bkf_lob&"|"&bkf_bu&"|"&$A11,_book!$E$2:$E$379,0))) -> — | P11: =IF(COUNTIFS(_book!$D$2:$D$379,"?*",_book!$C$2:$C$379,$A11,_book!$A$2:$A$379,bkc_lob,_book!$B$2:$B$379,bkc_bu)<>1,"—",INDEX(_book!$DQ$2:$DQ$379,MATCH(bkf_lob&"|"&bkf_bu&"|"&$A11,_book!$E$2:$E$379,0))) -> — | Q11: =IF(COUNTIFS(_book!$D$2:$D$379,"?*",_book!$C$2:$C$379,$A11,_book!$A$2:$A$379,bkc_lob,_book!$B$2:$B$379,bkc_bu)<>1,"—",INDEX(_book!$DR$2:$DR$379,MATCH(bkf_lob&"|"&bkf_bu&"|"&$A11,_book!$E$2:$E$379,0))) -> — | R11: =SUMIFS(_book!$AC$2:$AC$379,_book!$C$2:$C$379,$A11,_book!$A$2:$A$379,bkc_lob,_book!$B$2:$B$379,bkc_bu) -> 18 | S11: =SUMIFS(_book!$AD$2:$AD$379,_book!$C$2:$C$379,$A11,_book!$A$2:$A$379,bkc_lob,_book!$B$2:$B$379,bkc_bu) -> 12 | T11: =IF(SUMIFS(_book!$F$2:$F$379,_book!$C$2:$C$379,$A11,_book!$A$2:$A$379,bkc_lob,_book!$B$2:$B$379,bkc_bu)=0,"—",SUMIFS(_book!$AH$2:$AH$379,_book!$C$2:$C$379,$A11,_book!$A$2:$A$379,bkc_lob,_book!$B$2:$B$379,bkc_bu)/SUMIFS(_book!$F$2:$F$379,_book!$C$2:$C$379,$A11,_book!$A$2:$A$379,bkc_lob,_book!$B$2:$B$379,bkc_bu)) -> 1.0492857 | U11: =IF(SUMIFS(_book!$F$2:$F$379,_book!$C$2:$C$379,$A11,_book!$A$2:$A$379,bkc_lob,_book!$B$2:$B$379,bkc_bu)=0,"—",SUMIFS(_book!$AI$2:$AI$379,_book!$C$2:$C$379,$A11,_book!$A$2:$A$379,bkc_lob,_book!$B$2:$B$379,bkc_bu)/SUMIFS(_book!$F$2:$F$379,_book!$C$2:$C$379,$A11,_book!$A$2:$A$379,bkc_lob,_book!$B$2:$B$379,bkc_bu)) -> 1.048447 | V11: =IF(SUMIFS(_book!$F$2:$F$379,_book!$C$2:$C$379,$A11,_book!$A$2:$A$379,bkc_lob,_book!$B$2:$B$379,bkc_bu)=0,"—",SUMIFS(_book!$AJ$2:$AJ$379,_book!$C$2:$C$379,$A11,_book!$A$2:$A$379,bkc_lob,_book!$B$2:$B$379,bkc_bu)/SUMIFS(_book!$F$2:$F$379,_book!$C$2:$C$379,$A11,_book!$A$2:$A$379,bkc_lob,_book!$B$2:$B$379,bkc_bu)) -> 0.92168347 | W11: =IF(SUMIFS(_book!$F$2:$F$379,_book!$C$2:$C$379,$A11,_book!$A$2:$A$379,bkc_lob,_book!$B$2:$B$379,bkc_bu)=0,"—",SUMIFS(_book!$AN$2:$AN$379,_book!$C$2:$C$379,$A11,_book!$A$2:$A$379,bkc_lob,_book!$B$2:$B$379,bkc_bu)/SUMIFS(_book!$F$2:$F$379,_book!$C$2:$C$379,$A11,_book!$A$2:$A$379,bkc_lob,_book!$B$2:$B$379,bkc_bu)) -> 0.63808683 | X11: =IF(SUMIFS(_book!$F$2:$F$379,_book!$C$2:$C$379,$A11,_book!$A$2:$A$379,bkc_lob,_book!$B$2:$B$379,bkc_bu)=0,"—",SUMIFS(_book!$AK$2:$AK$379,_book!$C$2:$C$379,$A11,_book!$A$2:$A$379,bkc_lob,_book!$B$2:$B$379,bkc_bu)/SUMIFS(_book!$F$2:$F$379,_book!$C$2:$C$379,$A11,_book!$A$2:$A$379,bkc_lob,_book!$B$2:$B$379,bkc_bu)) -> 1.0007706 | Y11: =IF(SUMIFS(_book!$F$2:$F$379,_book!$C$2:$C$379,$A11,_book!$A$2:$A$379,bkc_lob,_book!$B$2:$B$379,bkc_bu)=0,"—",SUMIFS(_book!$AL$2:$AL$379,_book!$C$2:$C$379,$A11,_book!$A$2:$A$379,bkc_lob,_book!$B$2:$B$379,bkc_bu)/SUMIFS(_book!$F$2:$F$379,_book!$C$2:$C$379,$A11,_book!$A$2:$A$379,bkc_lob,_book!$B$2:$B$379,bkc_bu)) -> 1.0075477 | Z11: =IF(SUMIFS(_book!$F$2:$F$379,_book!$C$2:$C$379,$A11,_book!$A$2:$A$379,bkc_lob,_book!$B$2:$B$379,bkc_bu)=0,"—",SUMIFS(_book!$AM$2:$AM$379,_book!$C$2:$C$379,$A11,_book!$A$2:$A$379,bkc_lob,_book!$B$2:$B$379,bkc_bu)/SUMIFS(_book!$F$2:$F$379,_book!$C$2:$C$379,$A11,_book!$A$2:$A$379,bkc_lob,_book!$B$2:$B$379,bkc_bu)) -> 1 | AA11: =IF(COUNTIFS(_book!$D$2:$D$379,"?*",_book!$C$2:$C$379,$A11,_book!$A$2:$A$379,bkc_lob,_book!$B$2:$B$379,bkc_bu)=0,"",IF(COUNTIFS(_book!$D$2:$D$379,"?*",_book!$C$2:$C$379,$A11,_book!$A$2:$A$379,bkc_lob,_book!$B$2:$B$379,bkc_bu)=1,$W11*$X11*$Y11*$Z11,IF(SUMIFS(_book!$F$2:$F$379,_book!$C$2:$C$379,$A11,_book!$A$2:$A$379,bkc_lob,_book!$B$2:$B$379,bkc_bu)=0,"—",SUMIFS(_book!$AO$2:$AO$379,_book!$C$2:$C$379,$A11,_book!$A$2:$A$379,bkc_lob,_book!$B$2:$B$379,bkc_bu)/SUMIFS(_book!$F$2:$F$379,_book!$C$2:$C$379,$A11,_book!$A$2:$A$379,bkc_lob,_book!$B$2:$B$379,bkc_bu)))) -> 0.64337359 | AB11: =IF(COUNTIFS(_book!$D$2:$D$379,"?*",_book!$C$2:$C$379,$A11,_book!$A$2:$A$379,bkc_lob,_book!$B$2:$B$379,bkc_bu)<=1,"",($AA11-$W11*$X11*$Y11*$Z11)*100) -> -0.0024762515 | AC11: =IF(SUMIFS(_book!$F$2:$F$379,_book!$C$2:$C$379,$A11,_book!$A$2:$A$379,bkc_lob,_book!$B$2:$B$379,bkc_bu)=0,"—",SUMIFS(_book!$AQ$2:$AQ$379,_book!$C$2:$C$379,$A11,_book!$A$2:$A$379,bkc_lob,_book!$B$2:$B$379,bkc_bu)/SUMIFS(_book!$F$2:$F$379,_book!$C$2:$C$379,$A11,_book!$A$2:$A$379,bkc_lob,_book!$B$2:$B$379,bkc_bu)) -> 0 | AD11: =IF(SUMIFS(_book!$F$2:$F$379,_book!$C$2:$C$379,$A11,_book!$A$2:$A$379,bkc_lob,_book!$B$2:$B$379,bkc_bu)=0,"—",SUMIFS(_book!$AR$2:$AR$379,_book!$C$2:$C$379,$A11,_book!$A$2:$A$379,bkc_lob,_book!$B$2:$B$379,bkc_bu)/SUMIFS(_book!$F$2:$F$379,_book!$C$2:$C$379,$A11,_book!$A$2:$A$379,bkc_lob,_book!$B$2:$B$379,bkc_bu)) -> 0.97228572 | AE11: =IF(SUMIFS(_book!$F$2:$F$379,_book!$C$2:$C$379,$A11,_book!$A$2:$A$379,bkc_lob,_book!$B$2:$B$379,bkc_bu)=0,"—",SUMIFS(_book!$AS$2:$AS$379,_book!$C$2:$C$379,$A11,_book!$A$2:$A$379,bkc_lob,_book!$B$2:$B$379,bkc_bu)/SUMIFS(_book!$F$2:$F$379,_book!$C$2:$C$379,$A11,_book!$A$2:$A$379,bkc_lob,_book!$B$2:$B$379,bkc_bu)) -> 1.0075477 | AF11: =IF(COUNTIFS(_book!$D$2:$D$379,"?*",_book!$C$2:$C$379,$A11,_book!$A$2:$A$379,bkc_lob,_book!$B$2:$B$379,bkc_bu)=0,"",IF(COUNTIFS(_book!$D$2:$D$379,"?*",_book!$C$2:$C$379,$A11,_book!$A$2:$A$379,bkc_lob,_book!$B$2:$B$379,bkc_bu)=1,$W11*(1+$AC11)*$AD11*$AE11*$Z11,IF(SUMIFS(_book!$F$2:$F$379,_book!$C$2:$C$379,$A11,_book!$A$2:$A$379,bkc_lob,_book!$B$2:$B$379,bkc_bu)=0,"—",SUMIFS(_book!$AP$2:$AP$379,_book!$C$2:$C$379,$A11,_book!$A$2:$A$379,bkc_lob,_book!$B$2:$B$379,bkc_bu)/SUMIFS(_book!$F$2:$F$379,_book!$C$2:$C$379,$A11,_book!$A$2:$A$379,bkc_lob,_book!$B$2:$B$379,bkc_bu)))) -> 0.6251805 | AG11: =IF(COUNTIFS(_book!$D$2:$D$379,"?*",_book!$C$2:$C$379,$A11,_book!$A$2:$A$379,bkc_lob,_book!$B$2:$B$379,bkc_bu)=0,"",IF(SUMIFS(_book!$V$2:$V$379,_book!$C$2:$C$379,$A11,_book!$A$2:$A$379,bkc_lob,_book!$B$2:$B$379,bkc_bu)=0,"—",SUMIFS(_book!$W$2:$W$379,_book!$C$2:$C$379,$A11,_book!$A$2:$A$379,bkc_lob,_book!$B$2:$B$379,bkc_bu)/SUMIFS(_book!$V$2:$V$379,_book!$C$2:$C$379,$A11,_book!$A$2:$A$379,bkc_lob,_book!$B$2:$B$379,bkc_bu))) -> — | AH11: =IF(SUMIFS(_book!$V$2:$V$379,_book!$C$2:$C$379,$A11,_book!$A$2:$A$379,bkc_lob,_book!$B$2:$B$379,bkc_bu)=0,"—",IF(SUMIFS(_book!$F$2:$F$379,_book!$C$2:$C$379,$A11,_book!$A$2:$A$379,bkc_lob,_book!$B$2:$B$379,bkc_bu)=0,"—",SUMIFS(_book!$AT$2:$AT$379,_book!$C$2:$C$379,$A11,_book!$A$2:$A$379,bkc_lob,_book!$B$2:$B$379,bkc_bu)/SUMIFS(_book!$F$2:$F$379,_book!$C$2:$C$379,$A11,_book!$A$2:$A$379,bkc_lob,_book!$B$2:$B$379,bkc_bu))) -> — | AI11: =IF(SUMIFS(_book!$V$2:$V$379,_book!$C$2:$C$379,$A11,_book!$A$2:$A$379,bkc_lob,_book!$B$2:$B$379,bkc_bu)=0,"—",($AH11-$AA11)*100) -> —
A12: GA | B12: =SUMIFS(_book!$F$2:$F$379,_book!$C$2:$C$379,$A12,_book!$A$2:$A$379,bkc_lob,_book!$B$2:$B$379,bkc_bu) -> 510000 | C12: =IF(SUMIFS(_book!$F$2:$F$379,_book!$C$2:$C$379,$A12,_book!$A$2:$A$379,bkc_lob,_book!$B$2:$B$379,bkc_bu)=0,"—",SUMIFS(_book!$AV$2:$AV$379,_book!$C$2:$C$379,$A12,_book!$A$2:$A$379,bkc_lob,_book!$B$2:$B$379,bkc_bu)/SUMIFS(_book!$F$2:$F$379,_book!$C$2:$C$379,$A12,_book!$A$2:$A$379,bkc_lob,_book!$B$2:$B$379,bkc_bu)) -> 0.92858824 | D12: =IF(SUMIFS(_book!$F$2:$F$379,_book!$C$2:$C$379,$A12,_book!$A$2:$A$379,bkc_lob,_book!$B$2:$B$379,bkc_bu)=0,"—",SUMIFS(_book!$AW$2:$AW$379,_book!$C$2:$C$379,$A12,_book!$A$2:$A$379,bkc_lob,_book!$B$2:$B$379,bkc_bu)/SUMIFS(_book!$F$2:$F$379,_book!$C$2:$C$379,$A12,_book!$A$2:$A$379,bkc_lob,_book!$B$2:$B$379,bkc_bu)) -> 0.91858824 | E12: =IF(SUMIFS(_book!$F$2:$F$379,_book!$C$2:$C$379,$A12,_book!$A$2:$A$379,bkc_lob,_book!$B$2:$B$379,bkc_bu)=0,"—",SUMIFS(_book!$AX$2:$AX$379,_book!$C$2:$C$379,$A12,_book!$A$2:$A$379,bkc_lob,_book!$B$2:$B$379,bkc_bu)/SUMIFS(_book!$F$2:$F$379,_book!$C$2:$C$379,$A12,_book!$A$2:$A$379,bkc_lob,_book!$B$2:$B$379,bkc_bu)) -> 0.93358824 | F12: =IF(COUNTIFS(_book!$D$2:$D$379,"?*",_book!$C$2:$C$379,$A12,_book!$A$2:$A$379,bkc_lob,_book!$B$2:$B$379,bkc_bu)<>1,"—",INDEX(_book!$DG$2:$DG$379,MATCH(bkf_lob&"|"&bkf_bu&"|"&$A12,_book!$E$2:$E$379,0))) -> — | G12: =IF(COUNTIFS(_book!$D$2:$D$379,"?*",_book!$C$2:$C$379,$A12,_book!$A$2:$A$379,bkc_lob,_book!$B$2:$B$379,bkc_bu)<>1,"—",INDEX(_book!$DH$2:$DH$379,MATCH(bkf_lob&"|"&bkf_bu&"|"&$A12,_book!$E$2:$E$379,0))) -> — | H12: =IF(COUNTIFS(_book!$D$2:$D$379,"?*",_book!$C$2:$C$379,$A12,_book!$A$2:$A$379,bkc_lob,_book!$B$2:$B$379,bkc_bu)<>1,"—",INDEX(_book!$DI$2:$DI$379,MATCH(bkf_lob&"|"&bkf_bu&"|"&$A12,_book!$E$2:$E$379,0))) -> — | I12: =IF(COUNTIFS(_book!$D$2:$D$379,"?*",_book!$C$2:$C$379,$A12,_book!$A$2:$A$379,bkc_lob,_book!$B$2:$B$379,bkc_bu)<>1,"—",INDEX(_book!$DJ$2:$DJ$379,MATCH(bkf_lob&"|"&bkf_bu&"|"&$A12,_book!$E$2:$E$379,0))) -> — | J12: =IF(COUNTIFS(_book!$D$2:$D$379,"?*",_book!$C$2:$C$379,$A12,_book!$A$2:$A$379,bkc_lob,_book!$B$2:$B$379,bkc_bu)<>1,"—",INDEX(_book!$DK$2:$DK$379,MATCH(bkf_lob&"|"&bkf_bu&"|"&$A12,_book!$E$2:$E$379,0))) -> — | K12: =IF(COUNTIFS(_book!$D$2:$D$379,"?*",_book!$C$2:$C$379,$A12,_book!$A$2:$A$379,bkc_lob,_book!$B$2:$B$379,bkc_bu)<>1,"—",INDEX(_book!$DL$2:$DL$379,MATCH(bkf_lob&"|"&bkf_bu&"|"&$A12,_book!$E$2:$E$379,0))) -> — | L12: =IF(COUNTIFS(_book!$D$2:$D$379,"?*",_book!$C$2:$C$379,$A12,_book!$A$2:$A$379,bkc_lob,_book!$B$2:$B$379,bkc_bu)<>1,"—",INDEX(_book!$DM$2:$DM$379,MATCH(bkf_lob&"|"&bkf_bu&"|"&$A12,_book!$E$2:$E$379,0))) -> — | M12: =IF(COUNTIFS(_book!$D$2:$D$379,"?*",_book!$C$2:$C$379,$A12,_book!$A$2:$A$379,bkc_lob,_book!$B$2:$B$379,bkc_bu)<>1,"—",INDEX(_book!$DN$2:$DN$379,MATCH(bkf_lob&"|"&bkf_bu&"|"&$A12,_book!$E$2:$E$379,0))) -> — | N12: =IF(COUNTIFS(_book!$D$2:$D$379,"?*",_book!$C$2:$C$379,$A12,_book!$A$2:$A$379,bkc_lob,_book!$B$2:$B$379,bkc_bu)<>1,"—",INDEX(_book!$DO$2:$DO$379,MATCH(bkf_lob&"|"&bkf_bu&"|"&$A12,_book!$E$2:$E$379,0))) -> — | O12: =IF(COUNTIFS(_book!$D$2:$D$379,"?*",_book!$C$2:$C$379,$A12,_book!$A$2:$A$379,bkc_lob,_book!$B$2:$B$379,bkc_bu)<>1,"—",INDEX(_book!$DP$2:$DP$379,MATCH(bkf_lob&"|"&bkf_bu&"|"&$A12,_book!$E$2:$E$379,0))) -> — | P12: =IF(COUNTIFS(_book!$D$2:$D$379,"?*",_book!$C$2:$C$379,$A12,_book!$A$2:$A$379,bkc_lob,_book!$B$2:$B$379,bkc_bu)<>1,"—",INDEX(_book!$DQ$2:$DQ$379,MATCH(bkf_lob&"|"&bkf_bu&"|"&$A12,_book!$E$2:$E$379,0))) -> — | Q12: =IF(COUNTIFS(_book!$D$2:$D$379,"?*",_book!$C$2:$C$379,$A12,_book!$A$2:$A$379,bkc_lob,_book!$B$2:$B$379,bkc_bu)<>1,"—",INDEX(_book!$DR$2:$DR$379,MATCH(bkf_lob&"|"&bkf_bu&"|"&$A12,_book!$E$2:$E$379,0))) -> — | R12: =SUMIFS(_book!$AC$2:$AC$379,_book!$C$2:$C$379,$A12,_book!$A$2:$A$379,bkc_lob,_book!$B$2:$B$379,bkc_bu) -> 12 | S12: =SUMIFS(_book!$AD$2:$AD$379,_book!$C$2:$C$379,$A12,_book!$A$2:$A$379,bkc_lob,_book!$B$2:$B$379,bkc_bu) -> 6 | T12: =IF(SUMIFS(_book!$F$2:$F$379,_book!$C$2:$C$379,$A12,_book!$A$2:$A$379,bkc_lob,_book!$B$2:$B$379,bkc_bu)=0,"—",SUMIFS(_book!$AH$2:$AH$379,_book!$C$2:$C$379,$A12,_book!$A$2:$A$379,bkc_lob,_book!$B$2:$B$379,bkc_bu)/SUMIFS(_book!$F$2:$F$379,_book!$C$2:$C$379,$A12,_book!$A$2:$A$379,bkc_lob,_book!$B$2:$B$379,bkc_bu)) -> 1.0246667 | U12: =IF(SUMIFS(_book!$F$2:$F$379,_book!$C$2:$C$379,$A12,_book!$A$2:$A$379,bkc_lob,_book!$B$2:$B$379,bkc_bu)=0,"—",SUMIFS(_book!$AI$2:$AI$379,_book!$C$2:$C$379,$A12,_book!$A$2:$A$379,bkc_lob,_book!$B$2:$B$379,bkc_bu)/SUMIFS(_book!$F$2:$F$379,_book!$C$2:$C$379,$A12,_book!$A$2:$A$379,bkc_lob,_book!$B$2:$B$379,bkc_bu)) -> 1.02611 | V12: =IF(SUMIFS(_book!$F$2:$F$379,_book!$C$2:$C$379,$A12,_book!$A$2:$A$379,bkc_lob,_book!$B$2:$B$379,bkc_bu)=0,"—",SUMIFS(_book!$AJ$2:$AJ$379,_book!$C$2:$C$379,$A12,_book!$A$2:$A$379,bkc_lob,_book!$B$2:$B$379,bkc_bu)/SUMIFS(_book!$F$2:$F$379,_book!$C$2:$C$379,$A12,_book!$A$2:$A$379,bkc_lob,_book!$B$2:$B$379,bkc_bu)) -> 0.92172289 | W12: =IF(SUMIFS(_book!$F$2:$F$379,_book!$C$2:$C$379,$A12,_book!$A$2:$A$379,bkc_lob,_book!$B$2:$B$379,bkc_bu)=0,"—",SUMIFS(_book!$AN$2:$AN$379,_book!$C$2:$C$379,$A12,_book!$A$2:$A$379,bkc_lob,_book!$B$2:$B$379,bkc_bu)/SUMIFS(_book!$F$2:$F$379,_book!$C$2:$C$379,$A12,_book!$A$2:$A$379,bkc_lob,_book!$B$2:$B$379,bkc_bu)) -> 0.63663922 | X12: =IF(SUMIFS(_book!$F$2:$F$379,_book!$C$2:$C$379,$A12,_book!$A$2:$A$379,bkc_lob,_book!$B$2:$B$379,bkc_bu)=0,"—",SUMIFS(_book!$AK$2:$AK$379,_book!$C$2:$C$379,$A12,_book!$A$2:$A$379,bkc_lob,_book!$B$2:$B$379,bkc_bu)/SUMIFS(_book!$F$2:$F$379,_book!$C$2:$C$379,$A12,_book!$A$2:$A$379,bkc_lob,_book!$B$2:$B$379,bkc_bu)) -> 0.99856962 | Y12: =IF(SUMIFS(_book!$F$2:$F$379,_book!$C$2:$C$379,$A12,_book!$A$2:$A$379,bkc_lob,_book!$B$2:$B$379,bkc_bu)=0,"—",SUMIFS(_book!$AL$2:$AL$379,_book!$C$2:$C$379,$A12,_book!$A$2:$A$379,bkc_lob,_book!$B$2:$B$379,bkc_bu)/SUMIFS(_book!$F$2:$F$379,_book!$C$2:$C$379,$A12,_book!$A$2:$A$379,bkc_lob,_book!$B$2:$B$379,bkc_bu)) -> 1.0074786 | Z12: =IF(SUMIFS(_book!$F$2:$F$379,_book!$C$2:$C$379,$A12,_book!$A$2:$A$379,bkc_lob,_book!$B$2:$B$379,bkc_bu)=0,"—",SUMIFS(_book!$AM$2:$AM$379,_book!$C$2:$C$379,$A12,_book!$A$2:$A$379,bkc_lob,_book!$B$2:$B$379,bkc_bu)/SUMIFS(_book!$F$2:$F$379,_book!$C$2:$C$379,$A12,_book!$A$2:$A$379,bkc_lob,_book!$B$2:$B$379,bkc_bu)) -> 1 | AA12: =IF(COUNTIFS(_book!$D$2:$D$379,"?*",_book!$C$2:$C$379,$A12,_book!$A$2:$A$379,bkc_lob,_book!$B$2:$B$379,bkc_bu)=0,"",IF(COUNTIFS(_book!$D$2:$D$379,"?*",_book!$C$2:$C$379,$A12,_book!$A$2:$A$379,bkc_lob,_book!$B$2:$B$379,bkc_bu)=1,$W12*$X12*$Y12*$Z12,IF(SUMIFS(_book!$F$2:$F$379,_book!$C$2:$C$379,$A12,_book!$A$2:$A$379,bkc_lob,_book!$B$2:$B$379,bkc_bu)=0,"—",SUMIFS(_book!$AO$2:$AO$379,_book!$C$2:$C$379,$A12,_book!$A$2:$A$379,bkc_lob,_book!$B$2:$B$379,bkc_bu)/SUMIFS(_book!$F$2:$F$379,_book!$C$2:$C$379,$A12,_book!$A$2:$A$379,bkc_lob,_book!$B$2:$B$379,bkc_bu)))) -> 0.6404618 | AB12: =IF(COUNTIFS(_book!$D$2:$D$379,"?*",_book!$C$2:$C$379,$A12,_book!$A$2:$A$379,bkc_lob,_book!$B$2:$B$379,bkc_bu)<=1,"",($AA12-$W12*$X12*$Y12*$Z12)*100) -> -0.0021116398 | AC12: =IF(SUMIFS(_book!$F$2:$F$379,_book!$C$2:$C$379,$A12,_book!$A$2:$A$379,bkc_lob,_book!$B$2:$B$379,bkc_bu)=0,"—",SUMIFS(_book!$AQ$2:$AQ$379,_book!$C$2:$C$379,$A12,_book!$A$2:$A$379,bkc_lob,_book!$B$2:$B$379,bkc_bu)/SUMIFS(_book!$F$2:$F$379,_book!$C$2:$C$379,$A12,_book!$A$2:$A$379,bkc_lob,_book!$B$2:$B$379,bkc_bu)) -> 0 | AD12: =IF(SUMIFS(_book!$F$2:$F$379,_book!$C$2:$C$379,$A12,_book!$A$2:$A$379,bkc_lob,_book!$B$2:$B$379,bkc_bu)=0,"—",SUMIFS(_book!$AR$2:$AR$379,_book!$C$2:$C$379,$A12,_book!$A$2:$A$379,bkc_lob,_book!$B$2:$B$379,bkc_bu)/SUMIFS(_book!$F$2:$F$379,_book!$C$2:$C$379,$A12,_book!$A$2:$A$379,bkc_lob,_book!$B$2:$B$379,bkc_bu)) -> 0.98820263 | AE12: =IF(SUMIFS(_book!$F$2:$F$379,_book!$C$2:$C$379,$A12,_book!$A$2:$A$379,bkc_lob,_book!$B$2:$B$379,bkc_bu)=0,"—",SUMIFS(_book!$AS$2:$AS$379,_book!$C$2:$C$379,$A12,_book!$A$2:$A$379,bkc_lob,_book!$B$2:$B$379,bkc_bu)/SUMIFS(_book!$F$2:$F$379,_book!$C$2:$C$379,$A12,_book!$A$2:$A$379,bkc_lob,_book!$B$2:$B$379,bkc_bu)) -> 0.996707 | AF12: =IF(COUNTIFS(_book!$D$2:$D$379,"?*",_book!$C$2:$C$379,$A12,_book!$A$2:$A$379,bkc_lob,_book!$B$2:$B$379,bkc_bu)=0,"",IF(COUNTIFS(_book!$D$2:$D$379,"?*",_book!$C$2:$C$379,$A12,_book!$A$2:$A$379,bkc_lob,_book!$B$2:$B$379,bkc_bu)=1,$W12*(1+$AC12)*$AD12*$AE12*$Z12,IF(SUMIFS(_book!$F$2:$F$379,_book!$C$2:$C$379,$A12,_book!$A$2:$A$379,bkc_lob,_book!$B$2:$B$379,bkc_bu)=0,"—",SUMIFS(_book!$AP$2:$AP$379,_book!$C$2:$C$379,$A12,_book!$A$2:$A$379,bkc_lob,_book!$B$2:$B$379,bkc_bu)/SUMIFS(_book!$F$2:$F$379,_book!$C$2:$C$379,$A12,_book!$A$2:$A$379,bkc_lob,_book!$B$2:$B$379,bkc_bu)))) -> 0.62688653 | AG12: =IF(COUNTIFS(_book!$D$2:$D$379,"?*",_book!$C$2:$C$379,$A12,_book!$A$2:$A$379,bkc_lob,_book!$B$2:$B$379,bkc_bu)=0,"",IF(SUMIFS(_book!$V$2:$V$379,_book!$C$2:$C$379,$A12,_book!$A$2:$A$379,bkc_lob,_book!$B$2:$B$379,bkc_bu)=0,"—",SUMIFS(_book!$W$2:$W$379,_book!$C$2:$C$379,$A12,_book!$A$2:$A$379,bkc_lob,_book!$B$2:$B$379,bkc_bu)/SUMIFS(_book!$V$2:$V$379,_book!$C$2:$C$379,$A12,_book!$A$2:$A$379,bkc_lob,_book!$B$2:$B$379,bkc_bu))) -> — | AH12: =IF(SUMIFS(_book!$V$2:$V$379,_book!$C$2:$C$379,$A12,_book!$A$2:$A$379,bkc_lob,_book!$B$2:$B$379,bkc_bu)=0,"—",IF(SUMIFS(_book!$F$2:$F$379,_book!$C$2:$C$379,$A12,_book!$A$2:$A$379,bkc_lob,_book!$B$2:$B$379,bkc_bu)=0,"—",SUMIFS(_book!$AT$2:$AT$379,_book!$C$2:$C$379,$A12,_book!$A$2:$A$379,bkc_lob,_book!$B$2:$B$379,bkc_bu)/SUMIFS(_book!$F$2:$F$379,_book!$C$2:$C$379,$A12,_book!$A$2:$A$379,bkc_lob,_book!$B$2:$B$379,bkc_bu))) -> — | AI12: =IF(SUMIFS(_book!$V$2:$V$379,_book!$C$2:$C$379,$A12,_book!$A$2:$A$379,bkc_lob,_book!$B$2:$B$379,bkc_bu)=0,"—",($AH12-$AA12)*100) -> —
